Workbook

Sheet PAINEL DE CONTROLE
A1: PAINEL DE CONTROLE UHT
C4: PROCESSO | F4: LINHA A3F-01 | I4: LINHA A3F-02 | L4: LINHA TBA8
C5: VTIS-01 | D5: 13697 | F5: A3 FLEX | G5: 28359 | I5: A3 FLEX | J5: 6544 | L5: TBA8 | M5: 37757
C6: ALEX 30 | D6: 13742 | F6: ACHX 30 | G6: 29646 | I6: ACHX 30 | J6: 6727 | L6: ACHX 22 | M6: 44333
F7: CAP 25 | G7: 10727 | I7: CAP 25 | J7: 6673 | L7: CBP 70 | M7: 25737
F8: CBP 32 | G8: 29012 | I8: CBP 32 | J8: 6545 | L8: TTS 51 | M8: 26588
A11: VTIS
B14: VTIS - PROCESSO | J14: HOMOGEINIZADOR ALEX 30
B15: MANUTENÇÃO | C15: FREQ HR | D15: HORAS | E15: STATUS | J15: MANUTENÇÃO | L15: FREQ HR | M15: HORAS | N15: STATUS
B16: ANEIS SMS | C16: 4000 | D16: =VTIS!K4 -> 91103 | J16: TROCA DAS GAXETAS | L16: 500 | M16: =HOMOGEINIZADOR!K3 -> 438
B17: CAMARA ASSEPTICA | C17: 6000 | D17: =VTIS!K9 -> 93103 | J17: LUBRIFICAÇÃO DO CARTER; REDUTOR E UNIDADE HID. | L17: 1500 | M17: =HOMOGEINIZADOR!K10 -> 1438
B18: INJETOR DE VAPOR SI53 | C18: 6000 | D18: =VTIS!K13 -> 93103 | J18: MOTOR M6 | L18: 8000 | M18: =HOMOGEINIZADOR!K29 -> -5742
B19: M2 | C19: 6000 | J19: PISTOES E BUCHAS DE BRONZE | L19: 1500 | M19: =HOMOGEINIZADOR!K13 -> -12242
B20: M5 | C20: 6000 | J20: BLOCO DE ADIMISSAO | L20: 3000 | M20: =HOMOGEINIZADOR!K15 -> -10742
B21: M8 | C21: 6000 | J21: TRAÇÃO DO HOMO | L21: 8000 | M21: =HOMOGEINIZADOR!K26 -> -5742
B22: M9 | C22: 6000
B23: M11 | C23: 6000 | D23: =VTIS!K31 -> 93103
A27: ENVASE UHT
C29: TPA3/FLEX 01 (21218/00372) | I29: TPA3/FLEX 02 (21218/00372)
C30: MANUTENÇÃO | E30: FREQ HR | F30: HORAS | G30: STATUS | I30: MANUTENÇÃO | K30: FREQ HR | L30: HORAS | M30: STATUS
C31: BOMBA DE PEROXIDO | E31: 2500 | F31: ='A3FLEX 01'!K3 -> #REF! | I31: BOMBA DE PEROXIDO | K31: 2500 | L31: ='A3FLEX 02'!K3 -> #REF!
C32: ROLAMENTOS DE ROLOS | E32: 2000 | F32: ='A3FLEX 01'!K14 -> -1710 | I32: ROLAMENTOS DE ROLOS | K32: 2000 | L32: ='A3FLEX 02'!K14 -> -4544
E33: 3000 | F33: ='A3FLEX 01'!K16 -> -710 | K33: 3000 | L33: ='A3FLEX 02'!K16 -> -3544
C34: TRANSPORTADOR ALIMENTAÇÃO | E34: 7000 | F34: ='A3FLEX 01'!K26 -> 3290 | I34: TRANSPORTADOR ALIMENTAÇÃO | K34: 7000 | L34: ='A3FLEX 02'!K26 -> 456
C35: CALHA DE DESCARTE | E35: 6000 | F35: ='A3FLEX 01'!K36 -> 2290 | I35: CALHA DE DESCARTE | K35: 6000 | L35: ='A3FLEX 02'!K36 -> -544
E36: 12000 | F36: ='A3FLEX 01'!K39 -> 8290 | K36: 12000 | L36: ='A3FLEX 02'!K39 -> 5456
C37: PULDOW DEVICE | E37: 5000 | F37: ='A3FLEX 01'!K41 -> 1290 | I37: PULDOW DEVICE | K37: 5000 | L37: ='A3FLEX 02'!K41 -> -1544
C38: DESCARREGADOR FFU | E38: 5000 | F38: ='A3FLEX 01'!K54 -> 1290 | I38: DESCARREGADOR FFU | K38: 5000 | L38: ='A3FLEX 02'!K54 -> -1544
E39: 10000 | F39: ='A3FLEX 01'!K56 -> 6290 | K39: 10000 | L39: ='A3FLEX 02'!K56 -> 3456
C40: ANÉIS DE FORMAÇÃO | E40: 1000 | F40: ='A3FLEX 01'!K59 -> -2710 | I40: ANÉIS DE FORMAÇÃO | K40: 1000 | L40: ='A3FLEX 02'!K59 -> -4446
C41: SIS. MANDIBULAS - UNID. DE FORMAÇÃO | E41: 1000 | F41: ='A3FLEX 01'!K63 -> -2710 | I41: SIS. MANDIBULAS - UNID. DE FORMAÇÃO | K41: 1000 | L41: ='[1]A3 FLEX 01'!$K$63 -> #REF!
E42: 2000 | F42: ='A3FLEX 01'!K64 -> -1710 | K42: 2000 | L42: ='A3FLEX 02'!K61 -> -5544
C43: BANHEIRA DE PERÓXIDO | E43: 2000 | F43: ='A3FLEX 01'!K66 -> -1710 | I43: BANHEIRA DE PERÓXIDO | K43: 2000 | L43: ='A3FLEX 02'!K66 -> -4544
C44: PISTÃO DE ACIONAMENTO DA FACA | E44: 2000 | F44: ='A3FLEX 01'!K68 -> -1710 | I44: PISTÃO DE ACIONAMENTO DA FACA | K44: 2000 | L44: ='A3FLEX 02'!K68 -> -4544
C45: REPARO DOS GANCHOS DE PRESSÃO | E45: 2000 | F45: ='A3FLEX 01'!K76 -> -1710 | I45: REPARO DOS GANCHOS DE PRESSÃO | K45: 2000 | L45: ='A3FLEX 02'!K76 -> -4544
C46: APLICADOR DE FITA | E46: 2000 | F46: ='[1]A3 FLEX 01'!$K$90 -> #REF! | I46: APLICADOR DE FITA | K46: 2000 | L46: ='A3FLEX 02'!K90 -> -4544
C47: SISTEMA DE MANDIBULA | E47: 2000 | F47: ='A3FLEX 01'!K92 -> -1710 | I47: SISTEMA DE MANDIBULA | K47: 2000 | L47: ='A3FLEX 02'!K92 -> -4544
E48: 4000 | F48: ='A3FLEX 01'!K97 -> 290 | K48: 4000 | L48: ='A3FLEX 02'!K97 -> -2544
E49: 5000 | F49: ='A3FLEX 01'!K98 -> 1290 | K49: 5000 | L49: ='A3FLEX 02'!K98 -> -1544
E50: 6000 | F50: ='A3FLEX 01'!K99 -> 2290 | K50: 6000 | L50: ='A3FLEX 02'!K99 -> -544
...

Sheet VTIS
A1: VTIS - PROCESSO
A2: SISTEMA | B2: PROG | C2: COD PROTHEUS | D2: COD TETRA | E2: DESCRIÇÃO | F2: QT | G2: FREQ. TROCA | H2: HOR. ATUAL | I2: ULT. TROCA | J2: PREVISÃO | K2: HORAS P/ MANT. | L2: DATA DE MANUTENÇÃO | M2: OBSERVAÇÃO | N2: MANUTENTOR | O2: DATA DE MANUTENÇÃO | P2: OBSERVAÇÃO | Q2: MANUTENTOR | R2: DATA DE MANUTENÇÃO | S2: OBSERVAÇÃO | T2: MANUTENTOR | U2: DATA DE MANUTENÇÃO | V2: OBSERVAÇÃO | W2: MANUTENTOR | X2: DATA DE MANUTENÇÃO | Y2: OBSERVAÇÃO | Z2: MANUTENTOR | AA2: DATA DE MANUTENÇÃO | AB2: OBSERVAÇÃO | AC2: MANUTENTOR | AD2: DATA DE MANUTENÇÃO | AE2: OBSERVAÇÃO | AF2: MANUTENTOR | AG2: DATA DE MANUTENÇÃO | AH2: OBSERVAÇÃO | AI2: MANUTENTOR | AJ2: DATA DE MANUTENÇÃO | AK2: OBSERVAÇÃO | AL2: MANUTENTOR | AM2: DATA DE MANUTENÇÃO | AN2: OBSERVAÇÃO | AO2: MANUTENTOR | AP2: DATA DE MANUTENÇÃO | AQ2: OBSERVAÇÃO | AR2: MANUTENTOR | AS2: DATA DE MANUTENÇÃO | AT2: OBSERVAÇÃO | AU2: MANUTENTOR
A3: FILTRO CULINÁRIO | C3: 06190002115 | E3: ANEL DE VEDAÇÃO | F3: 1 | G3: X | H3: =TODAY() -> 46046 | I3: 45323 | J3: =SUM(I3+G3) -> #VALUE! | K3: =J3-H3 -> #VALUE!
A4: ANEIS SMS | B4: 809 | C4: 06000001558 | D4: 6-3131703753 | E4: ANEL DE VEDACAO SMS 1" | F4: 10 | G4: 4000 | H4: ='PAINEL DE CONTROLE'!$D$5 -> 13697 | I4: 100800 | J4: =SUM(I4+G4) -> 104800 | K4: =J4-H4 -> 91103
C5: 06000001559 | D5: 6-3131703772 | E5: ANEL DE VEDACAO SMS 1.1/2" | F5: 20 | G5: 4000 | H5: ='PAINEL DE CONTROLE'!$D$5 -> 13697 | I5: 100800 | J5: =SUM(I5+G5) -> 104800 | K5: =J5-H5 -> 91103
C6: 06000001560 | D6: 6-3131703785 | E6: ANEL DE VEDACAO SMS 2" | F6: 60 | G6: 4000 | H6: ='PAINEL DE CONTROLE'!$D$5 -> 13697 | I6: 100800 | J6: =SUM(I6+G6) -> 104800 | K6: =J6-H6 -> 91103
C7: 06000001561 | D7: 6-3131703793 | E7: ANEL DE VEDACAO SMS 2.1/2" | F7: 15 | G7: 4000 | H7: ='PAINEL DE CONTROLE'!$D$5 -> 13697 | I7: 100800 | J7: =SUM(I7+G7) -> 104800 | K7: =J7-H7 -> 91103
C8: 06000001562 | D8: 6-3131703803 | E8: ANEL DE VEDACAO SMS 3" | F8: 10 | G8: 4000 | H8: ='PAINEL DE CONTROLE'!$D$5 -> 13697 | I8: 100800 | J8: =SUM(I8+G8) -> 104800 | K8: =J8-H8 -> 91103
A9: CAMARA DE VÁCUO | B9: 810 | C9: 06000003208 | D9: 90510-5540 | E9: ANEL DE BORRACHA | F9: 4 | G9: 6000 | H9: ='PAINEL DE CONTROLE'!$D$5 -> 13697 | I9: 100800 | J9: =SUM(I9+G9) -> 106800 | K9: =J9-H9 -> 93103
C10: 06000001566 | D10: 6-3180124811 | E10: ANEL DE BORRACHA | F10: 1 | G10: 6000 | H10: ='PAINEL DE CONTROLE'!$D$5 -> 13697 | I10: 100800 | J10: =SUM(I10+G10) -> 106800 | K10: =J10-H10 -> 93103
C11: =VLOOKUP(D11,'[1]2-Saldos em Estoque'!A1:C33546,2,0) -> #REF! | D11: 6-26019070 | E11: ORING | F11: 6 | G11: 6000 | H11: ='PAINEL DE CONTROLE'!$D$5 -> 13697 | I11: 100800 | J11: =SUM(I11+G11) -> 106800 | K11: =J11-H11 -> 93103
C12: =VLOOKUP(D12,'[1]2-Saldos em Estoque'!A2:C33547,2,0) -> #REF! | D12: 6-26019068 | E12: ORING | F12: 6 | G12: 6000 | H12: ='PAINEL DE CONTROLE'!$D$5 -> 13697 | I12: 100800 | J12: =SUM(I12+G12) -> 106800 | K12: =J12-H12 -> 93103
A13: INJETOR DE VAPOR SI53 | B13: 811 | C13: =VLOOKUP(D13,'[1]2-Saldos em Estoque'!A3:C33548,2,0) -> #REF! | D13: 6-3131703803 | E13: ANEL DE BORRACHA | F13: 1 | G13: 6000 | H13: ='PAINEL DE CONTROLE'!$D$5 -> 13697 | I13: 100800 | J13: =SUM(I13+G13) -> 106800 | K13: =J13-H13 -> 93103
C14: 06000017858 | D14: 90522-3724 | E14: ANEL DE VEDAÇÃO | F14: 1 | G14: 6000 | H14: ='PAINEL DE CONTROLE'!$D$5 -> 13697 | I14: 100800 | J14: =SUM(I14+G14) -> 106800 | K14: =J14-H14 -> 93103
C15: 06000017859 | D15: 90522-3727 | E15: ANEL DE VEDAÇÃO | F15: 1 | G15: 6000 | H15: ='PAINEL DE CONTROLE'!$D$5 -> 13697 | I15: 100800 | J15: =SUM(I15+G15) -> 106800 | K15: =J15-H15 -> 93103
C16: 06000017860 | D16: 90522-3728 | E16: ANEL DE VEDAÇÃO | F16: 1 | G16: 6000 | H16: ='PAINEL DE CONTROLE'!$D$5 -> 13697 | I16: 100800 | J16: =SUM(I16+G16) -> 106800 | K16: =J16-H16 -> 93103
A17: M2 BOMBA DE ALIMENTAÇÃO PARA ENVIO DE PRODUTO PARA O TROCADOR DE CALOR A PLACAS | B17: 812 | C17: =VLOOKUP(D17,'[1]2-Saldos em Estoque'!A7:C33552,2,0) -> #REF! | D17: 6-9611922111 | E17: REPARO DE VEDACAO BORRACHA | F17: 1 | G17: 2000 | H17: ='PAINEL DE CONTROLE'!$D$5 -> 13697 | I17: 100800 | J17: =SUM(I17+G17) -> 102800 | K17: =J17-H17 -> 89103
B18: 813 | C18: 06320000109 | E18: ROLAMENTO 6309 ZZ C3 | F18: 1 | G18: 6000 | H18: ='PAINEL DE CONTROLE'!$D$5 -> 13697 | I18: 100800 | J18: =SUM(I18+G18) -> 106800 | K18: =J18-H18 -> 93103
C19: 06320000083 | E19: ROLAMENTO 6209 ZZ C3 | F19: 1 | G19: 6000 | H19: ='PAINEL DE CONTROLE'!$D$5 -> 13697 | I19: 100800 | J19: =SUM(I19+G19) -> 106800 | K19: =J19-H19 -> 93103
A20: M5 BOMBA CENTRÍFUGA DE ALIMENTAÇÃO DE PRODUTO | B20: 814 | C20: 06000001931 | D20: 6-9611922226 | E20: SERVI KIT | F20: 1 | G20: 2000 | H20: ='PAINEL DE CONTROLE'!$D$5 -> 13697 | I20: 100800 | J20: =SUM(I20+G20) -> 102800 | K20: =J20-H20 -> 89103
B21: 815 | C21: 06320000109 | E21: ROLAMENTO 6309 ZZ C3 | F21: 1 | G21: 6000 | H21: ='PAINEL DE CONTROLE'!$D$5 -> 13697 | I21: 100800 | J21: =SUM(I21+G21) -> 106800 | K21: =J21-H21 -> 93103
C22: 06320000083 | E22: ROLAMENTO 6209 ZZ C3 | F22: 1 | G22: 6000 | H22: ='PAINEL DE CONTROLE'!$D$5 -> 13697 | I22: 100800 | J22: =SUM(I22+G22) -> 106800 | K22: =J22-H22 -> 93103
A23: M8 BOMBA CENTRÍFUGA DO SISTEMA DE REFRIGERAÇÃO DO CONDENSADOR | B23: 816 | C23: 06000002088 | D23: 6-9611922122 | E23: SELO DE VEDAÇÃO | F23: 1 | G23: 2000 | H23: ='PAINEL DE CONTROLE'!$D$5 -> 13697 | I23: 100800 | J23: =SUM(I23+G23) -> 102800 | K23: =J23-H23 -> 89103
B24: 817 | C24: 06320000102 | E24: ROLAMENTO 6308 ZZ C3 | F24: 1 | G24: 6000 | H24: ='PAINEL DE CONTROLE'!$D$5 -> 13697 | I24: 100800 | J24: =SUM(I24+G24) -> 106800 | K24: =J24-H24 -> 93103
C25: 06320000073 | E25: ROLAMENTO 6206 ZZ C3 | F25: 1 | G25: 6000 | H25: ='PAINEL DE CONTROLE'!$D$5 -> 13697 | I25: 100800 | J25: =SUM(I25+G25) -> 106800 | K25: =J25-H25 -> 93103
A26: M9 BOMBA CENTRÍFUGA DO CIRCUITO DE ÁGUA | B26: 818 | C26: 06000007032 | D26: 90503-2293 | E26: SELO MECÂNICO | F26: 1 | G26: 2000 | H26: ='PAINEL DE CONTROLE'!$D$5 -> 13697 | J26: =SUM(I26+G26) -> 2000 | K26: =J26-H26 -> -11697
C27: 06000011305 | D27: 90503-2919 | E27: CONJUNTO DE VEDAÇÃO | F27: 1 | G27: 2000 | H27: ='PAINEL DE CONTROLE'!$D$5 -> 13697 | J27: =SUM(I27+G27) -> 2000 | K27: =J27-H27 -> -11697
C28: 06000008125 | D28: 90503-1053 | E28: GAXETA DE VEDAÇÃO DE BORRACHA | F28: 1 | G28: 2000 | H28: ='PAINEL DE CONTROLE'!$D$5 -> 13697 | J28: =SUM(I28+G28) -> 2000 | K28: =J28-H28 -> -11697
B29: 819 | C29: 06320001277 | E29: ROLAMENTO 7308 BE | F29: 1 | G29: 6000 | H29: ='PAINEL DE CONTROLE'!$D$5 -> 13697 | J29: =SUM(I29+G29) -> 6000 | K29: =J29-H29 -> -7697
C30: 06320000073 | E30: ROLAMENTO 6206 ZZ C3 | F30: 1 | G30: 6000 | H30: ='PAINEL DE CONTROLE'!$D$5 -> 13697 | J30: =SUM(I30+G30) -> 6000 | K30: =J30-H30 -> -7697
A31: M11 BOMBA DE VÁCUO | C31: 06000008847 | D31: 90516-5521 | E31: CONJUNTO DE PECAS SOBRESSALENTES | F31: 1 | G31: 6000 | H31: ='PAINEL DE CONTROLE'!$D$5 -> 13697 | I31: 100800 | J31: =SUM(I31+G31) -> 106800 | K31: =J31-H31 -> 93103
C32: 06320000109 | E32: ROLAMENTO 6309 ZZ C3 | F32: 1 | G32: 6000 | H32: ='PAINEL DE CONTROLE'!$D$5 -> 13697 | I32: 100800 | J32: =SUM(I32+G32) -> 106800 | K32: =J32-H32 -> 93103
C33: 06320000080 | E33: ROLAMENTO 6208 ZZ C3 | F33: 1 | G33: 6000 | H33: ='PAINEL DE CONTROLE'!$D$5 -> 13697 | I33: 100800 | J33: =SUM(I33+G33) -> 106800 | K33: =J33-H33 -> 93103
A34: M12 UNIDADE DE ALIMENTAÇÃO DE CIP (SODA) (90510-2119) | B34: 820 | C34: 06000012581 | D34: 90510-2299 | E34: SPARE PART KIT | F34: 1 | G34: 3000 | H34: ='PAINEL DE CONTROLE'!$D$5 -> 13697 | J34: =SUM(I34+G34) -> 3000 | K34: =J34-H34 -> -10697
A35: M13 UNIDADE DE ALIMENTAÇÃO DE CIP (ÁCIDO) (90510-2119) | B35: 821 | C35: 06000012581 | D35: 90510-2299 | E35: SPARE PART KIT | F35: 1 | G35: 3000 | H35: ='PAINEL DE CONTROLE'!$D$5 -> 13697 | J35: =SUM(I35+G35) -> 3000 | K35: =J35-H35 -> -10697
A36: V04 VÁLVULA ESFERA DE ÁGUA DO SISTEMA DE REFRIGERAÇÃO DO CONDENSADOR | B36: 822 | C36: =VLOOKUP(D36,'[2]2-Saldos em Estoque'!$A$3:$F$37081,2,0) -> #REF! | D36: 6-3180121904 | E36: =VLOOKUP(D36,'[2]2-Saldos em Estoque'!$A$3:$F$37081,3,0) -> #REF! | F36: 1 | G36: 1000 | H36: ='PAINEL DE CONTROLE'!$D$5 -> 13697 | K36: =J36-H36 -> -13697
B37: 823 | C37: =VLOOKUP(D37,'[2]2-Saldos em Estoque'!$A$3:$F$37081,2,0) -> #REF! | D37: 6-9611923010 | E37: =VLOOKUP(D37,'[2]2-Saldos em Estoque'!$A$3:$F$37081,3,0) -> #REF! | F37: 1 | G37: 6000 | H37: ='PAINEL DE CONTROLE'!$D$5 -> 13697 | K37: =J37-H37 -> -13697
A38: V05 VÁLVULA DE CIP DO TANQUE DE EQUILÍBRIO | B38: 824 | C38: =VLOOKUP(D38,'[2]2-Saldos em Estoque'!$A$3:$F$37081,2,0) -> #REF! | D38: 6-9611920008 | E38: =VLOOKUP(D38,'[2]2-Saldos em Estoque'!$A$3:$F$37081,3,0) -> #REF! | F38: 1 | G38: 6000 | H38: ='PAINEL DE CONTROLE'!$D$5 -> 13697 | I38: 100800 | J38: =SUM(I38+G38) -> 106800 | K38: =J38-H38 -> 93103
B39: 825 | C39: =VLOOKUP(D39,'[2]2-Saldos em Estoque'!$A$3:$F$37081,2,0) -> #REF! | D39: 6-9611920010 | E39: =VLOOKUP(D39,'[2]2-Saldos em Estoque'!$A$3:$F$37081,3,0) -> #REF! | F39: 1 | G39: 2000 | H39: ='PAINEL DE CONTROLE'!$D$5 -> 13697 | I39: 100800 | J39: =SUM(I39+G39) -> 102800 | K39: =J39-H39 -> 89103
A40: V08 VÁLVULA DE CONTROLE DE ENTRADA DE PRODUTO PARA O TANQUE DE EQUILIBRIO | B40: 826 | C40: =VLOOKUP(D40,'[2]2-Saldos em Estoque'!$A$3:$F$37081,2,0) -> #REF! | D40: 6-99041858 | E40: =VLOOKUP(D40,'[2]2-Saldos em Estoque'!$A$3:$F$37081,3,0) -> #REF! | F40: 1 | G40: 12000 | H40: ='PAINEL DE CONTROLE'!$D$5 -> 13697 | J40: =SUM(I40+G40) -> 12000 | K40: =J40-H40 -> -1697
...

Sheet HOMOGEINIZADOR
A1: HOMOGEINIZADOR ALEX 30
A2: SISTEMA | B2: COD PROTHEUS | C2: COD TETRA | D2: DESCRIÇÃO | E2: U.M | F2: QT | G2: FRENQ. TROCA | H2: HOR. ATUAL | I2: ULT. TROCA | J2: PREVISÃO | K2: HORAS P/ MANT. | L2: DATA DE MANUTENÇÃO | M2: OBSERVAÇÃO | N2: MANUTENTOR | O2: DATA DE MANUTENÇÃO | P2: OBSERVAÇÃO | Q2: MANUTENTOR | R2: DATA DE MANUTENÇÃO | S2: OBSERVAÇÃO | T2: MANUTENTOR | U2: DATA DE MANUTENÇÃO | V2: OBSERVAÇÃO | W2: MANUTENTOR | X2: DATA DE MANUTENÇÃO | Y2: OBSERVAÇÃO | Z2: MANUTENTOR | AA2: DATA DE MANUTENÇÃO | AB2: OBSERVAÇÃO | AC2: MANUTENTOR | AD2: DATA DE MANUTENÇÃO | AE2: OBSERVAÇÃO | AF2: MANUTENTOR | AG2: DATA DE MANUTENÇÃO | AH2: OBSERVAÇÃO | AI2: MANUTENTOR | AJ2: DATA DE MANUTENÇÃO | AK2: OBSERVAÇÃO | AL2: MANUTENTOR | AM2: DATA DE MANUTENÇÃO | AN2: OBSERVAÇÃO | AO2: MANUTENTOR | AP2: DATA DE MANUTENÇÃO | AQ2: OBSERVAÇÃO | AR2: MANUTENTOR | AS2: DATA DE MANUTENÇÃO | AT2: OBSERVAÇÃO | AU2: MANUTENTOR | AV2: DATA DE MANUTENÇÃO | AW2: OBSERVAÇÃO | AX2: MANUTENTOR
A3: GAXETAS DOS PISTÕES - PROG: 11 CÓD BICOM - 0799-8016 SA PADRÃO - 243905 | B3: 06000001594 | C3: 6-4722273901 | D3: ANEL DE BORRACHA DO KIT VTIS | E3: PC | F3: 3 | G3: 500 | H3: ='PAINEL DE CONTROLE'!$D$6 -> 13742 | I3: 13680 | J3: =SUM(I3+G3) -> 14180 | K3: =SUM(J3-H3) -> 438 | L3: 45728
B4: 06000002113 | C4: 6-4722298801 | D4: VEDACAO DO KIT VTIS | E4: PC | F4: 3 | G4: 500 | H4: ='PAINEL DE CONTROLE'!$D$6 -> 13742 | I4: 13680 | J4: =SUM(I4+G4) -> 14180 | K4: =SUM(J4-H4) -> 438 | L4: 45728
B5: 06000012362 | C5: 6-4722141807 | D5: ANEL DA GUIA EM BORRACHA | E5: PC | F5: 6 | G5: 500 | H5: ='PAINEL DE CONTROLE'!$D$6 -> 13742 | I5: 13680 | J5: =SUM(I5+G5) -> 14180 | K5: =SUM(J5-H5) -> 438 | L5: 45728
B6: 06000001585 | C6: 6-4722093104 | D6: ANEL DE BORRACHA KIT VTIS E FLEX | E6: PC | F6: 3 | G6: 500 | H6: ='PAINEL DE CONTROLE'!$D$6 -> 13742 | I6: =$I$3 -> 13680 | J6: =SUM(I6+G6) -> 14180 | K6: =SUM(J6-H6) -> 438 | L6: 45728
B7: 06000003339 | C7: 6-4722529001 | D7: ANEL DE BORRACHA DO KIT VTIS | E7: PC | F7: 3 | G7: 500 | H7: ='PAINEL DE CONTROLE'!$D$6 -> 13742 | I7: =$I$3 -> 13680 | J7: =SUM(I7+G7) -> 14180 | K7: =SUM(J7-H7) -> 438 | L7: 45728
B8: 06000008662 | C8: 6-4723137046 | D8: ANEL DE VEDACAO DE BORRACHA | E8: PC | F8: 3 | G8: 500 | H8: ='PAINEL DE CONTROLE'!$D$6 -> 13742 | I8: =$I$3 -> 13680 | J8: =SUM(I8+G8) -> 14180 | K8: =SUM(J8-H8) -> 438 | L8: 45728
A9: BARREIRA DE VAPOR | B9: 06000001599 | C9: 6-4722528901 | D9: ANEL DE VEDACAO DE BORRACHA | E9: PC | F9: 6 | G9: 1500 | H9: ='PAINEL DE CONTROLE'!$D$6 -> 13742 | I9: 13680 | J9: =SUM(I9+G9) -> 15180 | K9: =SUM(J9-H9) -> 1438 | L9: 45728
A10: BLOCO DO MOTOR (CARTER) - PROG: 39 | B10: 06300000044 | D10: SHELL OMALA 220 | E10: BD | F10: 4 | G10: 1500 | H10: ='PAINEL DE CONTROLE'!$D$6 -> 13742 | I10: 13680 | J10: =SUM(I10+G10) -> 15180 | K10: =SUM(J10-H10) -> 1438 | L10: 45728
A11: CAIXA DE REDUÇÃO - PROG: 39 | B11: 06300000045 | D11: SHELL OMALA 320 | E11: L | F11: 20 | G11: 1500 | H11: ='PAINEL DE CONTROLE'!$D$6 -> 13742 | I11: =$I$10 -> 13680 | J11: =SUM(I11+G11) -> 15180 | K11: =SUM(J11-H11) -> 1438 | L11: 45728
A12: UNIDADE HIDRAULICA - PROG: 39 | B12: 06300000423 | D12: OLEO LUBRIFICANTE H1-0530 | E12: L | F12: 20 | G12: 1500 | H12: ='PAINEL DE CONTROLE'!$D$6 -> 13742 | I12: =$I$10 -> 13680 | J12: =SUM(I12+G12) -> 15180 | K12: =SUM(J12-H12) -> 1438 | L12: 45728
A13: PISTOES E BUCHAS DE ENCOSTO DE BRONZE - PROG: 97 | B13: 06000008643 | C13: 6-4722935303 | D13: PISTOES | E13: PC | F13: 3 | G13: 1500 | H13: ='PAINEL DE CONTROLE'!$D$6 -> 13742 | J13: =SUM(I13+G13) -> 1500 | K13: =SUM(J13-H13) -> -12242
B14: 06000003953 e 06000003210 | C14: 6-4722266201 | D14: BUCHAS ENCOSTO DE BRONZE | E14: PC | F14: 3 | G14: 1500 | H14: ='PAINEL DE CONTROLE'!$D$6 -> 13742 | I14: =I13 | J14: =SUM(I14+G14) -> 1500 | K14: =SUM(J14-H14) -> -12242
A15: BLOCO HOMOGENEIZADOR - PROG: 275 | B15: 6000013074 | C15: 6-4723137012 | D15: ORING | E15: PC | F15: 2 | G15: 3000 | H15: ='PAINEL DE CONTROLE'!$D$6 -> 13742 | J15: =SUM(I15+G15) -> 3000 | K15: =SUM(J15-H15) -> -10742
B16: 6000008757 | C16: 6-4723137015 | D16: ORING | E16: PC | F16: 5 | G16: 3000 | H16: ='PAINEL DE CONTROLE'!$D$6 -> 13742 | J16: =SUM(I16+G16) -> 3000 | K16: =SUM(J16-H16) -> -10742
B17: 6000001722 | C17: 6-4722715203 | D17: ANEL SUP | E17: PC | F17: 3 | G17: 3000 | H17: ='PAINEL DE CONTROLE'!$D$6 -> 13742 | J17: =SUM(I17+G17) -> 3000 | K17: =SUM(J17-H17) -> -10742
B18: 6000008919 | C18: 6-4723137035 | D18: ORING | E18: PC | F18: 2 | G18: 3000 | H18: ='PAINEL DE CONTROLE'!$D$6 -> 13742 | J18: =SUM(I18+G18) -> 3000 | K18: =SUM(J18-H18) -> -10742
B19: 6000010121 | C19: 6-4723137010 | D19: ORING | E19: PC | F19: 2 | G19: 3000 | H19: ='PAINEL DE CONTROLE'!$D$6 -> 13742 | J19: =SUM(I19+G19) -> 3000 | K19: =SUM(J19-H19) -> -10742
B20: 6000011685 | C20: 6-4723137006 | D20: ORING | E20: PC | F20: 2 | G20: 3000 | H20: ='PAINEL DE CONTROLE'!$D$6 -> 13742 | J20: =SUM(I20+G20) -> 3000 | K20: =SUM(J20-H20) -> -10742
B21: 6000001724 | C21: 6-4722715102 | D21: SUPORTE | E21: PC | F21: 2 | G21: 3000 | H21: ='PAINEL DE CONTROLE'!$D$6 -> 13742 | J21: =SUM(I21+G21) -> 3000 | K21: =SUM(J21-H21) -> -10742
B22: 6000001591 | C22: 6-4722141803 | D22: GUIA | E22: PC | F22: 4 | G22: 3000 | H22: ='PAINEL DE CONTROLE'!$D$6 -> 13742 | J22: =SUM(I22+G22) -> 3000 | K22: =SUM(J22-H22) -> -10742
B23: 6000009323 | C23: 6-4723137008 | D23: ORING | E23: PC | F23: 2 | G23: 3000 | H23: ='PAINEL DE CONTROLE'!$D$6 -> 13742 | J23: =SUM(I23+G23) -> 3000 | K23: =SUM(J23-H23) -> -10742
B24: 6000001717 | C24: 6-4306000007 | D24: GUIA | E24: PC | F24: 4 | G24: 3000 | H24: ='PAINEL DE CONTROLE'!$D$6 -> 13742 | J24: =SUM(I24+G24) -> 3000 | K24: =SUM(J24-H24) -> -10742
B25: 6000001606 | C25: 6-4722715302 | D25: SUPORTE | E25: PC | F25: 2 | G25: 3000 | H25: ='PAINEL DE CONTROLE'!$D$6 -> 13742 | J25: =SUM(I25+G25) -> 3000 | K25: =SUM(J25-H25) -> -10742
A26: TRAÇÃO DO HOMO | B26: 06000013836 | C26: 6-4723212308 | D26: CORREIA TRAPEZOIDAL XPC 3000 | E26: UN | F26: 4 | G26: 8000 | H26: ='PAINEL DE CONTROLE'!$D$6 -> 13742 | J26: =SUM(I26+G26) -> 8000 | K26: =SUM(J26-H26) -> -5742
B27: 06000003213 | C27: 6-4722198901 | D27: COIFA | E27: UN | F27: 3 | G27: 8000 | H27: ='PAINEL DE CONTROLE'!$D$6 -> 13742 | I27: =$I$26 | J27: =SUM(I27+G27) -> 8000 | K27: =SUM(J27-H27) -> -5742
B28: 06000017021 E 06000009668 | C28: 6-4723125106 | D28: ABRACADEIRA | E28: PC | F28: 3 | G28: 8000 | H28: ='PAINEL DE CONTROLE'!$D$6 -> 13742 | I28: =$I$26 | J28: =SUM(I28+G28) -> 8000 | K28: =SUM(J28-H28) -> -5742
A29: M6 MOTOR - PROG: 207 | B29: 06000018120 | C29: 90511-7186 | D29: ROLAMENTO 6313-C3 TRAZEIRO | E29: PC | F29: 1 | G29: 8000 | H29: ='PAINEL DE CONTROLE'!$D$6 -> 13742 | J29: =SUM(I29+G29) -> 8000 | K29: =SUM(J29-H29) -> -5742
B30: 06000018119 | C30: 90512-4023 | D30: ROLAMENTO 6319-C3 DIANTEIRO | E30: PC | F30: 1 | G30: 8000 | H30: ='PAINEL DE CONTROLE'!$D$6 -> 13742 | J30: =SUM(I30+G30) -> 8000 | K30: =SUM(J30-H30) -> -5742

Sheet A3FLEX 01
A1: TPA3/FLEX 01
A2: SISTEMA | B2: PROG | C2: COD PROTHEUS | D2: COD TETRA | E2: DESCRIÇÃO | F2: QT | G2: FRENQ. TROCA | H2: HOR. ATUAL | I2: ULT. TROCA | J2: PREVISÃO | K2: HORAS P/ MANT. | L2: DATA DE MANUTENÇÃO | M2: OBSERVAÇÃO | N2: MANUTENTOR | O2: DATA DE MANUTENÇÃO | P2: OBSERVAÇÃO | Q2: MANUTENTOR | R2: DATA DE MANUTENÇÃO | S2: OBSERVAÇÃO | T2: MANUTENTOR | U2: DATA DE MANUTENÇÃO | V2: OBSERVAÇÃO | W2: MANUTENTOR | X2: DATA DE MANUTENÇÃO | Y2: OBSERVAÇÃO | Z2: MANUTENTOR | AA2: DATA DE MANUTENÇÃO | AB2: OBSERVAÇÃO | AC2: MANUTENTOR | AD2: DATA DE MANUTENÇÃO | AE2: OBSERVAÇÃO | AF2: MANUTENTOR | AG2: DATA DE MANUTENÇÃO | AH2: OBSERVAÇÃO | AI2: MANUTENTOR | AJ2: DATA DE MANUTENÇÃO | AK2: OBSERVAÇÃO | AL2: MANUTENTOR | AM2: DATA DE MANUTENÇÃO | AN2: OBSERVAÇÃO | AO2: MANUTENTOR | AP2: DATA DE MANUTENÇÃO | AQ2: OBSERVAÇÃO | AR2: MANUTENTOR | AS2: DATA DE MANUTENÇÃO | AT2: OBSERVAÇÃO | AU2: MANUTENTOR | AV2: DATA DE MANUTENÇÃO | AW2: OBSERVAÇÃO | AX2: MANUTENTOR
A3: BOMBA DE PEROXIDO | C3: =VLOOKUP(D3,[1]Saldo!A2:B31275,2,0) -> #ERROR! | D3: 1255557-0000 | E3: JUNTA DE VEDACAO | F3: ='[1]PARAMETROS PREVENTIVA'!$D168 -> #REF! | G3: ='[1]PARAMETROS PREVENTIVA'!$E168 -> #REF! | H3: ='PAINEL DE CONTROLE'!$G$5 -> 28359 | I3: 24649 | J3: =I3+G3 -> #REF! | K3: =SUM(J3-H3) -> #REF!
C4: =VLOOKUP(D4,[1]Saldo!A3:B31276,2,0) -> #ERROR! | D4: 927422-0005 | E4: O-RING 36.2X3 SILICON | F4: ='[1]PARAMETROS PREVENTIVA'!$D169 -> #REF! | G4: ='[1]PARAMETROS PREVENTIVA'!$E169 -> #REF! | H4: ='PAINEL DE CONTROLE'!$G$5 -> 28359 | I4: 24649 | J4: =I4+G4 -> #REF! | K4: =SUM(J4-H4) -> #REF!
C5: =VLOOKUP(D5,[1]Saldo!A4:B31277,2,0) -> #ERROR! | D5: 927422-0006 | E5: O-RING 42.2X3 SILICON | F5: ='[1]PARAMETROS PREVENTIVA'!$D170 -> #REF! | G5: ='[1]PARAMETROS PREVENTIVA'!$E170 -> #REF! | H5: ='PAINEL DE CONTROLE'!$G$5 -> 28359 | I5: 24649 | J5: =I5+G5 -> #REF! | K5: =SUM(J5-H5) -> #REF!
C6: =VLOOKUP(D6,[1]Saldo!A5:B31278,2,0) -> #ERROR! | D6: 315229-0103 | E6: Square Ring, 23,1x30,1x3,7 | F6: ='[1]PARAMETROS PREVENTIVA'!$D171 -> #REF! | G6: ='[1]PARAMETROS PREVENTIVA'!$E171 -> #REF! | H6: ='PAINEL DE CONTROLE'!$G$5 -> 28359 | I6: 24649 | J6: =I6+G6 -> #REF! | K6: =SUM(J6-H6) -> #REF!
C7: =VLOOKUP(D7,[1]Saldo!A6:B31279,2,0) -> #ERROR! | D7: 315229-0104 | E7: Square Ring, 35,8x42,8x3,7 mm 1"1/2 FDA | F7: ='[1]PARAMETROS PREVENTIVA'!$D172 -> #REF! | G7: ='[1]PARAMETROS PREVENTIVA'!$E172 -> #REF! | H7: ='PAINEL DE CONTROLE'!$G$5 -> 28359 | I7: 24649 | J7: =I7+G7 -> #REF! | K7: =SUM(J7-H7) -> #REF!
C8: =VLOOKUP(D8,[1]Saldo!A7:B31280,2,0) -> #ERROR! | D8: 315229-0105 | E8: Square Ring, 48,5x55,5x3,7 mm 2" FDA | F8: ='[1]PARAMETROS PREVENTIVA'!$D173 -> #REF! | G8: ='[1]PARAMETROS PREVENTIVA'!$E173 -> #REF! | H8: ='PAINEL DE CONTROLE'!$G$5 -> 28359 | I8: 24649 | J8: =I8+G8 -> #REF! | K8: =SUM(J8-H8) -> #REF!
C9: =VLOOKUP(D9,[1]Saldo!A8:B31281,2,0) -> #ERROR! | D9: 315229-0107 | E9: Gaxeta 73,9x80,9x3,7 mm 2"1/2 FDA | F9: ='[1]PARAMETROS PREVENTIVA'!$D174 -> #REF! | G9: ='[1]PARAMETROS PREVENTIVA'!$E174 -> #REF! | H9: ='PAINEL DE CONTROLE'!$G$5 -> 28359 | I9: 24649 | J9: =I9+G9 -> #REF! | K9: =SUM(J9-H9) -> #REF!
C10: =VLOOKUP(D10,[1]Saldo!A9:B31282,2,0) -> #ERROR! | D10: 2734102-0000 | E10: Casquilho | F10: ='[1]PARAMETROS PREVENTIVA'!$D175 -> #REF! | G10: ='[1]PARAMETROS PREVENTIVA'!$E175 -> #REF! | H10: ='PAINEL DE CONTROLE'!$G$5 -> 28359 | I10: 24649 | J10: =I10+G10 -> #REF! | K10: =SUM(J10-H10) -> #REF!
C11: =VLOOKUP(D11,[1]Saldo!A10:B31283,2,0) -> #ERROR! | D11: 90458-0274 | E11: Disco para acoplamento | F11: ='[1]PARAMETROS PREVENTIVA'!$D176 -> #REF! | G11: ='[1]PARAMETROS PREVENTIVA'!$E176 -> #REF! | H11: ='PAINEL DE CONTROLE'!$G$5 -> 28359 | I11: 24649 | J11: =I11+G11 -> #REF! | K11: =SUM(J11-H11) -> #REF!
C12: =VLOOKUP(D12,[1]Saldo!A11:B31284,2,0) -> #ERROR! | D12: 90607-0389 | E12: Rolamento W 6203-2RS2/VT127 | F12: ='[1]PARAMETROS PREVENTIVA'!$D177 -> #REF! | G12: ='[1]PARAMETROS PREVENTIVA'!$E177 -> #REF! | H12: ='PAINEL DE CONTROLE'!$G$5 -> 28359 | I12: 24649 | J12: =I12+G12 -> #REF! | K12: =SUM(J12-H12) -> #REF!
C13: =VLOOKUP(D13,[1]Saldo!A12:B31285,2,0) -> #ERROR! | D13: 90091-0412 | E13: Seal Ring | F13: ='[1]PARAMETROS PREVENTIVA'!$D178 -> #REF! | G13: ='[1]PARAMETROS PREVENTIVA'!$E178 -> #REF! | H13: ='PAINEL DE CONTROLE'!$G$5 -> 28359 | I13: 24649 | J13: =I13+G13 -> #REF! | K13: =SUM(J13-H13) -> #REF!
A14: ROLAMENTOS DE ROLOS | C14: =VLOOKUP(D14,[1]Saldo!A13:B31286,2,0) -> #ERROR! | D14: 90458-1704 | E14: ROLAMENTO DE ESFERAS | F14: 7 | G14: 2000 | H14: ='PAINEL DE CONTROLE'!$G$5 -> 28359 | I14: 24649 | J14: =I14+G14 -> 26649 | K14: =SUM(J14-H14) -> -1710
C15: =VLOOKUP(D15,[1]Saldo!A14:B31287,2,0) -> #ERROR! | D15: 90214-0303 | E15: ANEL | F15: 7 | G15: 2000 | H15: ='PAINEL DE CONTROLE'!$G$5 -> 28359 | I15: 24649 | J15: =I15+G15 -> 26649 | K15: =SUM(J15-H15) -> -1710
C16: =VLOOKUP(D16,[1]Saldo!A15:B31288,2,0) -> #ERROR! | D16: 315753-0130 | E16: Anel de retenção DIN 472 47 SS | F16: 1 | G16: 3000 | H16: ='PAINEL DE CONTROLE'!$G$5 -> 28359 | I16: 24649 | J16: =I16+G16 -> 27649 | K16: =SUM(J16-H16) -> -710
C17: =VLOOKUP(D17,[1]Saldo!A16:B31289,2,0) -> #ERROR! | D17: 315753-0119 | E17: ANEL DE FR DIN 471 25 A2 | F17: 1 | G17: 3000 | H17: ='PAINEL DE CONTROLE'!$G$5 -> 28359 | I17: 24649 | J17: =I17+G17 -> 27649 | K17: =SUM(J17-H17) -> -710
C18: =VLOOKUP(D18,[1]Saldo!A17:B31290,2,0) -> #ERROR! | D18: 90608-5674 | E18: ROLAMENTO DE ESFERAS | F18: 1 | G18: 3000 | H18: ='PAINEL DE CONTROLE'!$G$5 -> 28359 | I18: 24649 | J18: =I18+G18 -> 27649 | K18: =SUM(J18-H18) -> -710
C19: =VLOOKUP(D19,[1]Saldo!A18:B31291,2,0) -> #ERROR! | D19: 90459-1650 | E19: ANEL VEDANTE | F19: 1 | G19: 3000 | H19: ='PAINEL DE CONTROLE'!$G$5 -> 28359 | I19: 24649 | J19: =I19+G19 -> 27649 | K19: =SUM(J19-H19) -> -710
C20: =VLOOKUP(D20,[1]Saldo!A19:B31292,2,0) -> #ERROR! | D20: 90600-6017 | E20: VEDANTE | F20: 2 | G20: 3000 | H20: ='PAINEL DE CONTROLE'!$G$5 -> 28359 | I20: 24649 | J20: =I20+G20 -> 27649 | K20: =SUM(J20-H20) -> -710
C21: =VLOOKUP(D21,[1]Saldo!A20:B31293,2,0) -> #ERROR! | D21: 90601-2426 | E21: Casquilho | F21: 2 | G21: 3000 | H21: ='PAINEL DE CONTROLE'!$G$5 -> 28359 | I21: 24649 | J21: =I21+G21 -> 27649 | K21: =SUM(J21-H21) -> -710
C22: =VLOOKUP(D22,[1]Saldo!A21:B31294,2,0) -> #ERROR! | D22: 90602-0271 | E22: VEDANTE | F22: 8 | G22: 3000 | H22: ='PAINEL DE CONTROLE'!$G$5 -> 28359 | I22: 24649 | J22: =I22+G22 -> 27649 | K22: =SUM(J22-H22) -> -710
C23: =VLOOKUP(D23,[1]Saldo!A22:B31295,2,0) -> #ERROR! | D23: 90606-6965 | E23: Rolamento | F23: 4 | G23: 3000 | H23: ='PAINEL DE CONTROLE'!$G$5 -> 28359 | I23: 24649 | J23: =I23+G23 -> 27649 | K23: =SUM(J23-H23) -> -710
C24: =VLOOKUP(D24,[1]Saldo!A23:B31296,2,0) -> #ERROR! | D24: 315205-0509 | E24: O-ring 10,78x2,62 mm | F24: 4 | G24: 3000 | H24: ='PAINEL DE CONTROLE'!$G$5 -> 28359 | I24: 24649 | J24: =I24+G24 -> 27649 | K24: =SUM(J24-H24) -> -710
C25: =VLOOKUP(D25,[1]Saldo!A24:B31297,2,0) -> #ERROR! | D25: 315205-0734 | E25: O-ring 47,29x2,62 mm | F25: 4 | G25: 3000 | H25: ='PAINEL DE CONTROLE'!$G$5 -> 28359 | I25: 24649 | J25: =I25+G25 -> 27649 | K25: =SUM(J25-H25) -> -710
A26: TRANSPORTADOR ALIMENTAÇÃO | C26: =VLOOKUP(D26,[1]Saldo!A25:B31298,2,0) -> #ERROR! | D26: 90091-0440 | E26: RETENTOR | F26: 3 | G26: 7000 | H26: ='PAINEL DE CONTROLE'!$G$5 -> 28359 | I26: 24649 | J26: =I26+G26 -> 31649 | K26: =SUM(J26-H26) -> 3290
C27: =VLOOKUP(D27,[1]Saldo!A26:B31299,2,0) -> #ERROR! | D27: 321309-0103 | E27: ROLAMENTO 6203 | F27: 6 | G27: 7000 | H27: ='PAINEL DE CONTROLE'!$G$5 -> 28359 | I27: 24649 | J27: =I27+G27 -> 31649 | K27: =SUM(J27-H27) -> 3290
C28: =VLOOKUP(D28,[1]Saldo!A27:B31300,2,0) -> #ERROR! | D28: 1498068-0000 | E28: ANEL VEDANTE | F28: 2 | G28: 7000 | H28: ='PAINEL DE CONTROLE'!$G$5 -> 28359 | I28: 24649 | J28: =I28+G28 -> 31649 | K28: =SUM(J28-H28) -> 3290
C29: =VLOOKUP(D29,[1]Saldo!A28:B31301,2,0) -> #ERROR! | D29: 321306-0105 | E29: ROLAMENTO 6005 | F29: 2 | G29: 7000 | H29: ='PAINEL DE CONTROLE'!$G$5 -> 28359 | I29: 24649 | J29: =I29+G29 -> 31649 | K29: =SUM(J29-H29) -> 3290
C30: =VLOOKUP(D30,[1]Saldo!A29:B31302,2,0) -> #ERROR! | D30: 90214-0219 | E30: ROLAMENTO DE ESFERAS | F30: 2 | G30: 7000 | H30: ='PAINEL DE CONTROLE'!$G$5 -> 28359 | I30: 24649 | J30: =I30+G30 -> 31649 | K30: =SUM(J30-H30) -> 3290
C31: =VLOOKUP(D31,[1]Saldo!A30:B31303,2,0) -> #ERROR! | D31: 90141-0019 | E31: ANEL DE RENTECAO DE ACO | F31: 2 | G31: 7000 | H31: ='PAINEL DE CONTROLE'!$G$5 -> 28359 | I31: 24649 | J31: =I31+G31 -> 31649 | K31: =SUM(J31-H31) -> 3290
C32: =VLOOKUP(D32,[1]Saldo!A31:B31304,2,0) -> #ERROR! | D32: 1144783-0000 | E32: CORREIA | F32: 1 | G32: 7000 | H32: ='PAINEL DE CONTROLE'!$G$5 -> 28359 | I32: 24649 | J32: =I32+G32 -> 31649 | K32: =SUM(J32-H32) -> 3290
C33: =VLOOKUP(D33,[1]Saldo!A32:B31305,2,0) -> #ERROR! | D33: 315751-0119 | E33: ANEL DE TRAVA DE ACO | F33: 2 | G33: 7000 | H33: ='PAINEL DE CONTROLE'!$G$5 -> 28359 | I33: 24649 | J33: =I33+G33 -> 31649 | K33: =SUM(J33-H33) -> 3290
C34: =VLOOKUP(D34,[1]Saldo!A33:B31306,2,0) -> #ERROR! | D34: 1144841-0000 | E34: CORREIA DE TRASMISSAO , DENTADA DE PLASTICO POLIURETANO REFORCADO COM MALHA DE ACO | F34: 1 | G34: 7000 | H34: ='PAINEL DE CONTROLE'!$G$5 -> 28359 | I34: 24649 | J34: =I34+G34 -> 31649 | K34: =SUM(J34-H34) -> 3290
C35: =VLOOKUP(D35,[1]Saldo!A34:B31307,2,0) -> #ERROR! | D35: 90091-0297 | E35: RETENTOR B+L UE 35 477 2 | F35: 2 | G35: 7000 | H35: ='PAINEL DE CONTROLE'!$G$5 -> 28359 | I35: 24649 | J35: =I35+G35 -> 31649 | K35: =SUM(J35-H35) -> 3290
A36: CALHA DE DESCARTE | C36: =VLOOKUP(D36,[1]Saldo!A35:B31308,2,0) -> #ERROR! | D36: 3015733-0000 | E36: Casquilho | F36: 2 | G36: 6000 | H36: ='PAINEL DE CONTROLE'!$G$5 -> 28359 | I36: 24649 | J36: =I36+G36 -> 30649 | K36: =SUM(J36-H36) -> 2290
C37: =VLOOKUP(D37,[1]Saldo!A36:B31309,2,0) -> #ERROR! | D37: 1478928-0000 | E37: CASQUILHO | F37: 4 | G37: 6000 | H37: ='PAINEL DE CONTROLE'!$G$5 -> 28359 | I37: 24649 | J37: =I37+G37 -> 30649 | K37: =SUM(J37-H37) -> 2290
C38: =VLOOKUP(D38,[1]Saldo!A37:B31310,2,0) -> #ERROR! | D38: 90235-0847 | E38: Flow controller | F38: 2 | G38: 6000 | H38: ='PAINEL DE CONTROLE'!$G$5 -> 28359 | I38: 24649 | J38: =I38+G38 -> 30649 | K38: =SUM(J38-H38) -> 2290
C39: =VLOOKUP(D39,[1]Saldo!A38:B31311,2,0) -> #ERROR! | D39: 3015731-0000 | E39: SUPORTE DE ACO | F39: 2 | G39: 12000 | H39: ='PAINEL DE CONTROLE'!$G$5 -> 28359 | I39: 24649 | J39: =I39+G39 -> 36649 | K39: =SUM(J39-H39) -> 8290
C40: =VLOOKUP(D40,[1]Saldo!A39:B31312,2,0) -> #ERROR! | D40: 3020023-0000 | E40: SUPORTE | F40: 2 | G40: 12000 | H40: ='PAINEL DE CONTROLE'!$G$5 -> 28359 | I40: 24649 | J40: =I40+G40 -> 36649 | K40: =SUM(J40-H40) -> 8290
...

Sheet HELIX 01
A1: ACUMULADOR HELIX 30 01
A2: SISTEMA | B2: COD PROTHEUS | C2: COD TETRA | D2: DESCRIÇÃO | E2: QT | F2: FRENQ. TROCA | G2: HOR. ATUAL | H2: ULT. TROCA | I2: PREVISÃO | J2: HORAS P/ MANT. | K2: DATA DE MANUTENÇÃO | L2: OBSERVAÇÃO | M2: MANUTENTOR | N2: DATA DE MANUTENÇÃO | O2: OBSERVAÇÃO | P2: MANUTENTOR | Q2: DATA DE MANUTENÇÃO | R2: OBSERVAÇÃO | S2: MANUTENTOR | T2: DATA DE MANUTENÇÃO | U2: OBSERVAÇÃO | V2: MANUTENTOR | W2: DATA DE MANUTENÇÃO | X2: OBSERVAÇÃO | Y2: MANUTENTOR | Z2: DATA DE MANUTENÇÃO | AA2: OBSERVAÇÃO | AB2: MANUTENTOR | AC2: DATA DE MANUTENÇÃO | AD2: OBSERVAÇÃO | AE2: MANUTENTOR | AF2: DATA DE MANUTENÇÃO | AG2: OBSERVAÇÃO | AH2: MANUTENTOR | AI2: DATA DE MANUTENÇÃO | AJ2: OBSERVAÇÃO | AK2: MANUTENTOR | AL2: DATA DE MANUTENÇÃO | AM2: OBSERVAÇÃO | AN2: MANUTENTOR | AO2: DATA DE MANUTENÇÃO | AP2: OBSERVAÇÃO | AQ2: MANUTENTOR
A3: ARANHA E RODAS DO HELIX | B3: =VLOOKUP(C3,[1]Saldo!A2:B31275,2,0) -> #ERROR! | C3: 90606-3401 | D3: ESCOVA | E3: 4 | F3: 4000 | G3: ='PAINEL DE CONTROLE'!$G$6 -> 29646 | H3: 25839 | I3: =SUM(H3+F3) -> 29839 | J3: =SUM(I3-G3) -> 193
B4: =VLOOKUP(C4,[1]Saldo!A3:B31276,2,0) -> #ERROR! | C4: 90608-3877 | D4: ROLAMENTO W6204 | E4: 6 | F4: 6000 | G4: ='PAINEL DE CONTROLE'!$G$6 -> 29646 | H4: 25839 | I4: =SUM(H4+F4) -> 31839 | J4: =SUM(I4-G4) -> 2193
B5: =VLOOKUP(C5,[1]Saldo!A4:B31277,2,0) -> #ERROR! | C5: 3169909-0000 | D5: ANEL TRAVA | E5: 4 | F5: 6000 | G5: ='PAINEL DE CONTROLE'!$G$6 -> 29646 | H5: 25839 | I5: =SUM(H5+F5) -> 31839 | J5: =SUM(I5-G5) -> 2193
B6: =VLOOKUP(C6,[1]Saldo!A5:B31278,2,0) -> #ERROR! | C6: 90608-7154 | D6: ROLAMENTO W6001 | E6: 23 | F6: 6000 | G6: ='PAINEL DE CONTROLE'!$G$6 -> 29646 | H6: 25839 | I6: =SUM(H6+F6) -> 31839 | J6: =SUM(I6-G6) -> 2193
B7: =VLOOKUP(C7,[1]Saldo!A6:B31279,2,0) -> #ERROR! | C7: 2948868-0000 | D7: ROLAMENTO | E7: 4 | F7: 6000 | G7: ='PAINEL DE CONTROLE'!$G$6 -> 29646 | H7: 25839 | I7: =SUM(H7+F7) -> 31839 | J7: =SUM(I7-G7) -> 2193
B8: =VLOOKUP(C8,[1]Saldo!A7:B31280,2,0) -> #ERROR! | C8: 2727353-0000 | D8: CORREIA | E8: 1 | F8: 6000 | G8: ='PAINEL DE CONTROLE'!$G$6 -> 29646 | H8: 25839 | I8: =SUM(H8+F8) -> 31839 | J8: =SUM(I8-G8) -> 2193
B9: =VLOOKUP(C9,[1]Saldo!A8:B31281,2,0) -> #ERROR! | C9: 90603-2403 | D9: ROLAMENTO W6004 | E9: 6 | F9: 6000 | G9: ='PAINEL DE CONTROLE'!$G$6 -> 29646 | H9: 25839 | I9: =SUM(H9+F9) -> 31839 | J9: =SUM(I9-G9) -> 2193
B10: =VLOOKUP(C10,[1]Saldo!A9:B31282,2,0) -> #ERROR! | C10: 90608-3874 | D10: ROLAMENTO W608 | E10: 1 | F10: 6000 | G10: ='PAINEL DE CONTROLE'!$G$6 -> 29646 | H10: 25839 | I10: =SUM(H10+F10) -> 31839 | J10: =SUM(I10-G10) -> 2193
B11: =VLOOKUP(C11,[1]Saldo!A10:B31283,2,0) -> #ERROR! | C11: 2727356-0000 | D11: ROLAMENTO CATRACA | E11: 1 | F11: 6000 | G11: ='PAINEL DE CONTROLE'!$G$6 -> 29646 | H11: 25839 | I11: =SUM(H11+F11) -> 31839 | J11: =SUM(I11-G11) -> 2193
B12: =VLOOKUP(C12,[1]Saldo!A11:B31284,2,0) -> #ERROR! | C12: 2948958-0000 | D12: CORREIA | E12: 1 | F12: 6000 | G12: ='PAINEL DE CONTROLE'!$G$6 -> 29646 | H12: 25839 | I12: =SUM(H12+F12) -> 31839 | J12: =SUM(I12-G12) -> 2193
B13: =VLOOKUP(C13,[1]Saldo!A12:B31285,2,0) -> #ERROR! | C13: 2528297-0000 | D13: ANEL TRAVA INTERNO | E13: 5 | F13: 6000 | G13: ='PAINEL DE CONTROLE'!$G$6 -> 29646 | H13: 25839 | I13: =SUM(H13+F13) -> 31839 | J13: =SUM(I13-G13) -> 2193
B14: =VLOOKUP(C14,[1]Saldo!A13:B31286,2,0) -> #ERROR! | C14: 2727357-0000 | D14: RETENTOR | E14: 2 | F14: 6000 | G14: ='PAINEL DE CONTROLE'!$G$6 -> 29646 | H14: 25839 | I14: =SUM(H14+F14) -> 31839 | J14: =SUM(I14-G14) -> 2193
B15: =VLOOKUP(C15,[1]Saldo!A14:B31287,2,0) -> #ERROR! | C15: 2855235-0000 | D15: CORREIA | E15: 1 | F15: 6000 | G15: ='PAINEL DE CONTROLE'!$G$6 -> 29646 | H15: 25839 | I15: =SUM(H15+F15) -> 31839 | J15: =SUM(I15-G15) -> 2193
... B18: =VLOOKUP(C18,[1]Saldo!A17:B31290,2,0) -> #ERROR! | C18: 2727233-0000 | D18: ENGRENAGEM | E18: 3 | F18: 6000 | G18: ='PAINEL DE CONTROLE'!$G$6 -> 29646 | H18: 25839 | I18: =SUM(H18+F18) -> 31839 | J18: =SUM(I18-G18) -> 2193

Sheet CAPPER 01
A1: CAPPER 25
A2: SISTEMA | B2: COD PROTHEUS | C2: COD TETRA | D2: DESCRIÇÃO | E2: QT | F2: FREQ. TROCA | G2: HOR. ATUAL | H2: ULT. TROCA | I2: PREVISÃO | J2: HORAS P/ MANT. | K2: DATA DE MANUTENÇÃO | L2: OBSERVAÇÃO | M2: MANUTENTOR | N2: DATA DE MANUTENÇÃO | O2: OBSERVAÇÃO | P2: MANUTENTOR | Q2: DATA DE MANUTENÇÃO | R2: OBSERVAÇÃO | S2: MANUTENTOR | T2: DATA DE MANUTENÇÃO | U2: OBSERVAÇÃO | V2: MANUTENTOR | W2: DATA DE MANUTENÇÃO | X2: OBSERVAÇÃO | Y2: MANUTENTOR | Z2: DATA DE MANUTENÇÃO | AA2: OBSERVAÇÃO | AB2: MANUTENTOR | AC2: DATA DE MANUTENÇÃO | AD2: OBSERVAÇÃO | AE2: MANUTENTOR | AF2: DATA DE MANUTENÇÃO | AG2: OBSERVAÇÃO | AH2: MANUTENTOR | AI2: DATA DE MANUTENÇÃO | AJ2: OBSERVAÇÃO | AK2: MANUTENTOR | AL2: DATA DE MANUTENÇÃO | AM2: OBSERVAÇÃO | AN2: MANUTENTOR | AO2: DATA DE MANUTENÇÃO | AP2: OBSERVAÇÃO | AQ2: MANUTENTOR | AR2: DATA DE MANUTENÇÃO | AS2: OBSERVAÇÃO | AT2: MANUTENTOR
A3: UNIDADE APLICADORA DE TAMPA PROG: 33 | B3: 06000008972 | C3: 3399156-0000 | D3: CORREIA | E3: 2 | F3: 1000 | G3: ='PAINEL DE CONTROLE'!$G$7 -> 10727 | H3: 7100 | I3: =SUM(H3+F3) -> 8100 | J3: =SUM(I3-G3) -> -2627
B4: VIRAR CORREIA DO CAPPER | E4: X | F4: 500 | G4: ='PAINEL DE CONTROLE'!$G$7 -> 10727 | H4: 7100 | I4: =SUM(H4+F4) -> 7600 | J4: =SUM(I4-G4) -> -3127
A5: UNIDADE DE FREIO DE ENTRADA PROG. 30 (SPC 1-72 / 1-74 / 1-76) | B5: 06000000658 | C5: 315221-0145 | D5: RETENTOR | E5: 2 | F5: 2000 | G5: ='PAINEL DE CONTROLE'!$G$7 -> 10727 | H5: 7100 | I5: =SUM(H5+F5) -> 9100 | J5: =SUM(I5-G5) -> -1627
B6: 06000001414 | C6: 315753-0124 | D6: ANEL TRAVA | E6: 4 | F6: 2000 | G6: ='PAINEL DE CONTROLE'!$G$7 -> 10727 | H6: 7100 | I6: =SUM(H6+F6) -> 9100 | J6: =SUM(I6-G6) -> -1627
B7: 06000013318 | C7: 90608-7194 | D7: ROLAMENTO W6003 | E7: 10 | F7: 2000 | G7: ='PAINEL DE CONTROLE'!$G$7 -> 10727 | H7: 7100 | I7: =SUM(H7+F7) -> 9100 | J7: =SUM(I7-G7) -> -1627
B8: 06000004074 | C8: 315220-0130 | D8: RETENTOR | E8: 2 | F8: 2000 | G8: ='PAINEL DE CONTROLE'!$G$7 -> 10727 | H8: 7100 | I8: =SUM(H8+F8) -> 9100 | J8: =SUM(I8-G8) -> -1627
B9: 06000012080 | C9: 351523-0219 | D9: ANEL | E9: 4 | F9: 2000 | G9: ='PAINEL DE CONTROLE'!$G$7 -> 10727 | H9: 7100 | I9: =SUM(H9+F9) -> 9100 | J9: =SUM(I9-G9) -> -1627
B10: 06000003983 | C10: 315220-0172 | D10: RETENTOR | E10: 4 | F10: 2000 | G10: ='PAINEL DE CONTROLE'!$G$7 -> 10727 | H10: 7100 | I10: =SUM(H10+F10) -> 9100 | J10: =SUM(I10-G10) -> -1627
B11: 06000003047 | C11: 315221-0137 | D11: RETENTOR | E11: 8 | F11: 2000 | G11: ='PAINEL DE CONTROLE'!$G$7 -> 10727 | H11: 7100 | I11: =SUM(H11+F11) -> 9100 | J11: =SUM(I11-G11) -> -1627
C12: 351692-0015 | D12: CORREIA | E12: 4 | F12: 2000 | G12: ='PAINEL DE CONTROLE'!$G$7 -> 10727 | H12: 7100 | I12: =SUM(H12+F12) -> 9100 | J12: =SUM(I12-G12) -> -1627
C13: 533237-0000 | D13: CAVILHA EIXO | E13: 8 | F13: 2000 | G13: ='PAINEL DE CONTROLE'!$G$7 -> 10727 | H13: 7100 | I13: =SUM(H13+F13) -> 9100 | J13: =SUM(I13-G13) -> -1627
A14: UNIDADE DAS CORREIAS LATERAL PROG: 31 | B14: 06000011366 | C14: 90459-1819 | D14: CORREIA | E14: 2 | F14: 3000 | G14: ='PAINEL DE CONTROLE'!$G$7 -> 10727 | H14: 7100 | I14: =SUM(H14+F14) -> 10100 | J14: =SUM(I14-G14) -> -627
B15: 06000013368 | C15: 90603-3556 | D15: ROLAMENTO W 6202-2RS | E15: 8 | F15: 3000 | G15: ='PAINEL DE CONTROLE'!$G$7 -> 10727 | H15: 7100 | I15: =SUM(H15+F15) -> 10100 | J15: =SUM(I15-G15) -> -627
A16: UNIDADE APLICADORA DE TAMPA | C16: 90608-7174 | D16: ROLAMENTO W6002 | E16: 12 | F16: 4000 | G16: ='PAINEL DE CONTROLE'!$G$7 -> 10727 | H16: 7100 | I16: =SUM(H16+F16) -> 11100 | J16: =SUM(I16-G16) -> 373
C17: 3235244-0000 | D17: BUCHA | E17: 4 | F17: 4000 | G17: ='PAINEL DE CONTROLE'!$G$7 -> 10727 | H17: 7100 | I17: =SUM(H17+F17) -> 11100 | J17: =SUM(I17-G17) -> 373
C18: 3235246-0000 | D18: ANEL | E18: 2 | F18: 4000 | G18: ='PAINEL DE CONTROLE'!$G$7 -> 10727 | H18: 7100 | I18: =SUM(H18+F18) -> 11100 | J18: =SUM(I18-G18) -> 373
C19: 3238271-0000 | D19: BUCHA | E19: 2 | F19: 4000 | G19: ='PAINEL DE CONTROLE'!$G$7 -> 10727 | H19: 7100 | I19: =SUM(H19+F19) -> 11100 | J19: =SUM(I19-G19) -> 373
A20: UNIDADE DE FREIO DE ENTRADA PROG. ** | B20: 06000012792 | C20: 90606-8951 | D20: CORRENTE ACO INOX | E20: 1 | F20: 6000 | G20: ='PAINEL DE CONTROLE'!$G$7 -> 10727 | H20: 7100 | I20: =SUM(H20+F20) -> 13100 | J20: =SUM(I20-G20) -> 2373

Sheet CARD-32 01
A1: CARDBOARD PACKER 32 01
A2: SISTEMA | B2: COD PROTHEUS | C2: COD TETRA | D2: DESCRIÇÃO | E2: QT | F2: FRENQ. TROCA | G2: HOR. ATUAL | H2: ULT. TROCA | I2: PREVISÃO | J2: HORAS P/ MANT. | K2: DATA DE MANUTENÇÃO | L2: OBSERVAÇÃO | M2: MANUTENTOR | N2: DATA DE MANUTENÇÃO | O2: OBSERVAÇÃO | P2: MANUTENTOR | Q2: DATA DE MANUTENÇÃO | R2: OBSERVAÇÃO | S2: MANUTENTOR | T2: DATA DE MANUTENÇÃO | U2: OBSERVAÇÃO | V2: MANUTENTOR | W2: DATA DE MANUTENÇÃO | X2: OBSERVAÇÃO | Y2: MANUTENTOR | Z2: DATA DE MANUTENÇÃO | AA2: OBSERVAÇÃO | AB2: MANUTENTOR | AC2: DATA DE MANUTENÇÃO | AD2: OBSERVAÇÃO | AE2: MANUTENTOR | AF2: DATA DE MANUTENÇÃO | AG2: OBSERVAÇÃO | AH2: MANUTENTOR | AI2: DATA DE MANUTENÇÃO | AJ2: OBSERVAÇÃO | AK2: MANUTENTOR | AL2: DATA DE MANUTENÇÃO | AM2: OBSERVAÇÃO | AN2: MANUTENTOR | AO2: DATA DE MANUTENÇÃO | AP2: OBSERVAÇÃO | AQ2: MANUTENTOR | AR2: DATA DE MANUTENÇÃO | AS2: OBSERVAÇÃO | AT2: MANUTENTOR
A3: UNIDADE DE AIMENTAÇÃO - FREIO DE ENTRADA (SPC 1.5 1-4 / 1.5 1-1) | B3: =VLOOKUP(C3,[1]Saldo!A2:B31275,2,0) -> #ERROR! | C3: 90601-0786 | D3: CORREIA | E3: 4 | F3: 4000 | G3: ='PAINEL DE CONTROLE'!$G$8 -> 29012 | H3: 25198 | I3: =SUM(H3+F3) -> 29198 | J3: =SUM(I3-G3) -> 186
B4: =VLOOKUP(C4,[1]Saldo!A3:B31276,2,0) -> #ERROR! | C4: 06190000619 | D4: RETENTOR 30X40X7 | E4: 4 | F4: 2000 | G4: ='PAINEL DE CONTROLE'!$G$8 -> 29012 | H4: 25198 | I4: =SUM(H4+F4) -> 27198 | J4: =SUM(I4-G4) -> -1814
B5: =VLOOKUP(C5,[1]Saldo!A4:B31277,2,0) -> #ERROR! | C5: 315207-0714 | D5: ANEL | E5: 2 | F5: 2000 | G5: ='PAINEL DE CONTROLE'!$G$8 -> 29012 | H5: 25198 | I5: =SUM(H5+F5) -> 27198 | J5: =SUM(I5-G5) -> -1814
B6: =VLOOKUP(C6,[1]Saldo!A5:B31278,2,0) -> #ERROR! | C6: 344224-0203 | D6: ROLAMENTO W 6003-2RS | E6: 8 | F6: 2000 | G6: ='PAINEL DE CONTROLE'!$G$8 -> 29012 | H6: 25198 | I6: =SUM(H6+F6) -> 27198 | J6: =SUM(I6-G6) -> -1814
B7: =VLOOKUP(C7,[1]Saldo!A6:B31279,2,0) -> #ERROR! | C7: 344224-0204 | D7: ROLAMENTO W 6004-2RS | E7: 2 | F7: 2000 | G7: ='PAINEL DE CONTROLE'!$G$8 -> 29012 | H7: 25198 | I7: =SUM(H7+F7) -> 27198 | J7: =SUM(I7-G7) -> -1814
B8: =VLOOKUP(C8,[1]Saldo!A7:B31280,2,0) -> #ERROR! | C8: 90091-0418 | D8: ANEL V-RING | E8: 4 | F8: 2000 | G8: ='PAINEL DE CONTROLE'!$G$8 -> 29012 | H8: 25198 | I8: =SUM(H8+F8) -> 27198 | J8: =SUM(I8-G8) -> -1814
B9: =VLOOKUP(C9,[1]Saldo!A8:B31281,2,0) -> #ERROR! | C9: 90141-0017 | D9: ANEL | E9: 4 | F9: 2000 | G9: ='PAINEL DE CONTROLE'!$G$8 -> 29012 | H9: 25198 | I9: =SUM(H9+F9) -> 27198 | J9: =SUM(I9-G9) -> -1814
A10: FORMAÇÃO PADRÃO - EMPURRADOR DE AGRUPAMENTO (SPC 2.2 1-1) | B10: =VLOOKUP(C10,[1]Saldo!A9:B31282,2,0) -> #ERROR! | C10: 315751-0109 | D10: ='[1]PARAMETROS PREVENTIVA'!$C675 -> #REF! | E10: ='[1]PARAMETROS PREVENTIVA'!$D675 -> #REF! | F10: ='[1]PARAMETROS PREVENTIVA'!$E675 -> #REF! | G10: ='PAINEL DE CONTROLE'!$G$8 -> 29012 | H10: 25198 | I10: =SUM(H10+F10) -> #REF! | J10: =SUM(I10-G10) -> #REF!
B11: =VLOOKUP(C11,[1]Saldo!A10:B31283,2,0) -> #ERROR! | C11: 90240-0222 | D11: ='[1]PARAMETROS PREVENTIVA'!$C676 -> #REF! | E11: ='[1]PARAMETROS PREVENTIVA'!$D676 -> #REF! | F11: ='[1]PARAMETROS PREVENTIVA'!$E676 -> #REF! | G11: ='PAINEL DE CONTROLE'!$G$8 -> 29012 | H11: 25198 | I11: =SUM(H11+F11) -> #REF! | J11: =SUM(I11-G11) -> #REF!
B12: =VLOOKUP(C12,[1]Saldo!A11:B31284,2,0) -> #ERROR! | C12: 90603-2945 | D12: ='[1]PARAMETROS PREVENTIVA'!$C677 -> #REF! | E12: ='[1]PARAMETROS PREVENTIVA'!$D677 -> #REF! | F12: ='[1]PARAMETROS PREVENTIVA'!$E677 -> #REF! | G12: ='PAINEL DE CONTROLE'!$G$8 -> 29012 | H12: 25198 | I12: =SUM(H12+F12) -> #REF! | J12: =SUM(I12-G12) -> #REF!
A13: FORMAÇÃO PADRÃO - PLACA GUIA DE TRANSFERENCIA (SPC 2.2 4-1 / 2.2 8-1) | B13: =VLOOKUP(C13,[1]Saldo!A12:B31285,2,0) -> #ERROR! | C13: 321153-0140 | D13: ='[1]PARAMETROS PREVENTIVA'!$C678 -> #REF! | E13: ='[1]PARAMETROS PREVENTIVA'!$D678 -> #REF! | F13: ='[1]PARAMETROS PREVENTIVA'!$E678 -> #REF! | G13: ='PAINEL DE CONTROLE'!$G$8 -> 29012 | H13: 25198 | I13: =SUM(H13+F13) -> #REF! | J13: =SUM(I13-G13) -> #REF!
B14: =VLOOKUP(C14,[1]Saldo!A13:B31286,2,0) -> #ERROR! | C14: 3215909-0000 | D14: ='[1]PARAMETROS PREVENTIVA'!$C679 -> #REF! | E14: ='[1]PARAMETROS PREVENTIVA'!$D679 -> #REF! | F14: ='[1]PARAMETROS PREVENTIVA'!$E679 -> #REF! | G14: ='PAINEL DE CONTROLE'!$G$8 -> 29012 | H14: 25198 | I14: =SUM(H14+F14) -> #REF! | J14: =SUM(I14-G14) -> #REF!
B15: =VLOOKUP(C15,[1]Saldo!A14:B31287,2,0) -> #ERROR! | C15: 90335-0031 | D15: ='[1]PARAMETROS PREVENTIVA'!$C680 -> #REF! | E15: ='[1]PARAMETROS PREVENTIVA'!$D680 -> #REF! | F15: ='[1]PARAMETROS PREVENTIVA'!$E680 -> #REF! | G15: ='PAINEL DE CONTROLE'!$G$8 -> 29012 | H15: 25198 | I15: =SUM(H15+F15) -> #REF! | J15: =SUM(I15-G15) -> #REF!
A16: FORMAÇÃO PADRÃO - CORPO DE TRANSFERENCIA (SPC 2.2.10 5-2 / 2.2 15-2) | B16: =VLOOKUP(C16,[1]Saldo!A15:B31288,2,0) -> #ERROR! | C16: 2750061-0000 | D16: ='[1]PARAMETROS PREVENTIVA'!$C681 -> #REF! | E16: ='[1]PARAMETROS PREVENTIVA'!$D681 -> #REF! | F16: ='[1]PARAMETROS PREVENTIVA'!$E681 -> #REF! | G16: ='PAINEL DE CONTROLE'!$G$8 -> 29012 | H16: 25198 | I16: =SUM(H16+F16) -> #REF! | J16: =SUM(I16-G16) -> #REF!
B17: =VLOOKUP(C17,[1]Saldo!A16:B31289,2,0) -> #ERROR! | C17: 315751-0115 | D17: ='[1]PARAMETROS PREVENTIVA'!$C682 -> #REF! | E17: ='[1]PARAMETROS PREVENTIVA'!$D682 -> #REF! | F17: ='[1]PARAMETROS PREVENTIVA'!$E682 -> #REF! | G17: ='PAINEL DE CONTROLE'!$G$8 -> 29012 | H17: 25198 | I17: =SUM(H17+F17) -> #REF! | J17: =SUM(I17-G17) -> #REF!
B18: =VLOOKUP(C18,[1]Saldo!A17:B31290,2,0) -> #ERROR! | C18: 315751-0116 | D18: ='[1]PARAMETROS PREVENTIVA'!$C683 -> #REF! | E18: ='[1]PARAMETROS PREVENTIVA'!$D683 -> #REF! | F18: ='[1]PARAMETROS PREVENTIVA'!$E683 -> #REF! | G18: ='PAINEL DE CONTROLE'!$G$8 -> 29012 | H18: 25198 | I18: =SUM(H18+F18) -> #REF! | J18: =SUM(I18-G18) -> #REF!
B19: =VLOOKUP(C19,[1]Saldo!A18:B31291,2,0) -> #ERROR! | C19: 344226-0103 | D19: ='[1]PARAMETROS PREVENTIVA'!$C684 -> #REF! | E19: ='[1]PARAMETROS PREVENTIVA'!$D684 -> #REF! | F19: ='[1]PARAMETROS PREVENTIVA'!$E684 -> #REF! | G19: ='PAINEL DE CONTROLE'!$G$8 -> 29012 | H19: 25198 | I19: =SUM(H19+F19) -> #REF! | J19: =SUM(I19-G19) -> #REF!
B20: =VLOOKUP(C20,[1]Saldo!A19:B31292,2,0) -> #ERROR! | C20: 312155-0329 | D20: ='[1]PARAMETROS PREVENTIVA'!$C685 -> #REF! | E20: ='[1]PARAMETROS PREVENTIVA'!$D685 -> #REF! | F20: ='[1]PARAMETROS PREVENTIVA'!$E685 -> #REF! | G20: ='PAINEL DE CONTROLE'!$G$8 -> 29012 | H20: 25198 | I20: =SUM(H20+F20) -> #REF! | J20: =SUM(I20-G20) -> #REF!
B21: =VLOOKUP(C21,[1]Saldo!A20:B31293,2,0) -> #ERROR! | C21: 90459-0679 | D21: ='[1]PARAMETROS PREVENTIVA'!$C686 -> #REF! | E21: ='[1]PARAMETROS PREVENTIVA'!$D686 -> #REF! | F21: ='[1]PARAMETROS PREVENTIVA'!$E686 -> #REF! | G21: ='PAINEL DE CONTROLE'!$G$8 -> 29012 | H21: 25198 | I21: =SUM(H21+F21) -> #REF! | J21: =SUM(I21-G21) -> #REF!
B22: =VLOOKUP(C22,[1]Saldo!A21:B31294,2,0) -> #ERROR! | C22: 90603-4534 | D22: ='[1]PARAMETROS PREVENTIVA'!$C687 -> #REF! | E22: ='[1]PARAMETROS PREVENTIVA'!$D687 -> #REF! | F22: ='[1]PARAMETROS PREVENTIVA'!$E687 -> #REF! | G22: ='PAINEL DE CONTROLE'!$G$8 -> 29012 | H22: 25198 | I22: =SUM(H22+F22) -> #REF! | J22: =SUM(I22-G22) -> #REF!
A23: FORMAÇÃO PADRÃO - BRAÇO DE PARADA (SPC 2.2 4-3) | B23: =VLOOKUP(C23,[1]Saldo!A22:B31295,2,0) -> #ERROR! | C23: 90603-3541 | D23: ='[1]PARAMETROS PREVENTIVA'!$C688 -> #REF! | E23: ='[1]PARAMETROS PREVENTIVA'!$D688 -> #REF! | F23: ='[1]PARAMETROS PREVENTIVA'!$E688 -> #REF! | G23: ='PAINEL DE CONTROLE'!$G$8 -> 29012 | H23: 25198 | I23: =SUM(H23+F23) -> #REF! | J23: =SUM(I23-G23) -> #REF!
A24: AGRUPAMENTO - TRANSFERÊNCIA | B24: =VLOOKUP(C24,[1]Saldo!A23:B31296,2,0) -> #ERROR! | C24: 321141-0140 | D24: ='[1]PARAMETROS PREVENTIVA'!$C689 -> #REF! | E24: ='[1]PARAMETROS PREVENTIVA'!$D689 -> #REF! | F24: ='[1]PARAMETROS PREVENTIVA'!$E689 -> #REF! | G24: ='PAINEL DE CONTROLE'!$G$8 -> 29012 | H24: 25198 | I24: =SUM(H24+F24) -> #REF! | J24: =SUM(I24-G24) -> #REF!
B25: =VLOOKUP(C25,[1]Saldo!A24:B31297,2,0) -> #ERROR! | C25: 321161-0221 | D25: ='[1]PARAMETROS PREVENTIVA'!$C690 -> #REF! | E25: ='[1]PARAMETROS PREVENTIVA'!$D690 -> #REF! | F25: ='[1]PARAMETROS PREVENTIVA'!$E690 -> #REF! | G25: ='PAINEL DE CONTROLE'!$G$8 -> 29012 | H25: 25198 | I25: =SUM(H25+F25) -> #REF! | J25: =SUM(I25-G25) -> #REF!
B26: =VLOOKUP(C26,[1]Saldo!A25:B31298,2,0) -> #ERROR! | C26: 90347-0007 | D26: ='[1]PARAMETROS PREVENTIVA'!$C691 -> #REF! | E26: ='[1]PARAMETROS PREVENTIVA'!$D691 -> #REF! | F26: ='[1]PARAMETROS PREVENTIVA'!$E691 -> #REF! | G26: ='PAINEL DE CONTROLE'!$G$8 -> 29012 | H26: 25198 | I26: =SUM(H26+F26) -> #REF! | J26: =SUM(I26-G26) -> #REF!
B27: =VLOOKUP(C27,[1]Saldo!A26:B31299,2,0) -> #ERROR! | C27: 90608-9474 | D27: ='[1]PARAMETROS PREVENTIVA'!$C692 -> #REF! | E27: ='[1]PARAMETROS PREVENTIVA'!$D692 -> #REF! | F27: ='[1]PARAMETROS PREVENTIVA'!$E692 -> #REF! | G27: ='PAINEL DE CONTROLE'!$G$8 -> 29012 | H27: 25198 | I27: =SUM(H27+F27) -> #REF! | J27: =SUM(I27-G27) -> #REF!
B28: =VLOOKUP(C28,[1]Saldo!A27:B31300,2,0) -> #ERROR! | C28: 321161-0142 | D28: ='[1]PARAMETROS PREVENTIVA'!$C693 -> #REF! | E28: ='[1]PARAMETROS PREVENTIVA'!$D693 -> #REF! | F28: ='[1]PARAMETROS PREVENTIVA'!$E693 -> #REF! | G28: ='PAINEL DE CONTROLE'!$G$8 -> 29012 | H28: 25198 | I28: =SUM(H28+F28) -> #REF! | J28: =SUM(I28-G28) -> #REF!
B29: =VLOOKUP(C29,[1]Saldo!A28:B31301,2,0) -> #ERROR! | C29: 90607-5194 | D29: ='[1]PARAMETROS PREVENTIVA'!$C694 -> #REF! | E29: ='[1]PARAMETROS PREVENTIVA'!$D694 -> #REF! | F29: ='[1]PARAMETROS PREVENTIVA'!$E694 -> #REF! | G29: ='PAINEL DE CONTROLE'!$G$8 -> 29012 | H29: 25198 | I29: =SUM(H29+F29) -> #REF! | J29: =SUM(I29-G29) -> #REF!
B30: =VLOOKUP(C30,[1]Saldo!A29:B31302,2,0) -> #ERROR! | C30: 321153-0136 | D30: ='[1]PARAMETROS PREVENTIVA'!$C695 -> #REF! | E30: ='[1]PARAMETROS PREVENTIVA'!$D695 -> #REF! | F30: ='[1]PARAMETROS PREVENTIVA'!$E695 -> #REF! | G30: ='PAINEL DE CONTROLE'!$G$8 -> 29012 | H30: 25198 | I30: =SUM(H30+F30) -> #REF! | J30: =SUM(I30-G30) -> #REF!
B31: =VLOOKUP(C31,[1]Saldo!A30:B31303,2,0) -> #ERROR! | C31: 2771221-0000 | D31: ='[1]PARAMETROS PREVENTIVA'!$C696 -> #REF! | E31: ='[1]PARAMETROS PREVENTIVA'!$D696 -> #REF! | F31: ='[1]PARAMETROS PREVENTIVA'!$E696 -> #REF! | G31: ='PAINEL DE CONTROLE'!$G$8 -> 29012 | H31: 25198 | I31: =SUM(H31+F31) -> #REF! | J31: =SUM(I31-G31) -> #REF!
B32: =VLOOKUP(C32,[1]Saldo!A31:B31304,2,0) -> #ERROR! | C32: 2787843-0000 | D32: ='[1]PARAMETROS PREVENTIVA'!$C697 -> #REF! | E32: ='[1]PARAMETROS PREVENTIVA'!$D697 -> #REF! | F32: ='[1]PARAMETROS PREVENTIVA'!$E697 -> #REF! | G32: ='PAINEL DE CONTROLE'!$G$8 -> 29012 | H32: 25198 | I32: =SUM(H32+F32) -> #REF! | J32: =SUM(I32-G32) -> #REF!
B33: =VLOOKUP(C33,[1]Saldo!A32:B31305,2,0) -> #ERROR! | C33: 90240-0257 | D33: ='[1]PARAMETROS PREVENTIVA'!$C698 -> #REF! | E33: ='[1]PARAMETROS PREVENTIVA'!$D698 -> #REF! | F33: ='[1]PARAMETROS PREVENTIVA'!$E698 -> #REF! | G33: ='PAINEL DE CONTROLE'!$G$8 -> 29012 | H33: 25198 | I33: =SUM(H33+F33) -> #REF! | J33: =SUM(I33-G33) -> #REF!
A34: CADEIA DE ESTAÇÃO | B34: =VLOOKUP(C34,[1]Saldo!A33:B31306,2,0) -> #ERROR! | C34: 1065841-0000 | D34: ='[1]PARAMETROS PREVENTIVA'!$C699 -> #REF! | E34: ='[1]PARAMETROS PREVENTIVA'!$D699 -> #REF! | F34: ='[1]PARAMETROS PREVENTIVA'!$E699 -> #REF! | G34: ='PAINEL DE CONTROLE'!$G$8 -> 29012 | H34: 25198 | I34: =SUM(H34+F34) -> #REF! | J34: =SUM(I34-G34) -> #REF!
B35: =VLOOKUP(C35,[1]Saldo!A34:B31307,2,0) -> #ERROR! | C35: 315751-0116 | D35: ='[1]PARAMETROS PREVENTIVA'!$C700 -> #REF! | E35: ='[1]PARAMETROS PREVENTIVA'!$D700 -> #REF! | F35: ='[1]PARAMETROS PREVENTIVA'!$E700 -> #REF! | G35: ='PAINEL DE CONTROLE'!$G$8 -> 29012 | H35: 25198 | I35: =SUM(H35+F35) -> #REF! | J35: =SUM(I35-G35) -> #REF!
B36: =VLOOKUP(C36,[1]Saldo!A35:B31308,2,0) -> #ERROR! | C36: 90288-0317 | D36: ='[1]PARAMETROS PREVENTIVA'!$C701 -> #REF! | E36: ='[1]PARAMETROS PREVENTIVA'!$D701 -> #REF! | F36: ='[1]PARAMETROS PREVENTIVA'!$E701 -> #REF! | G36: ='PAINEL DE CONTROLE'!$G$8 -> 29012 | H36: 25198 | I36: =SUM(H36+F36) -> #REF! | J36: =SUM(I36-G36) -> #REF!
B37: =VLOOKUP(C37,[1]Saldo!A36:B31309,2,0) -> #ERROR! | C37: 90141-0020 | D37: ='[1]PARAMETROS PREVENTIVA'!$C702 -> #REF! | E37: ='[1]PARAMETROS PREVENTIVA'!$D702 -> #REF! | F37: ='[1]PARAMETROS PREVENTIVA'!$E702 -> #REF! | G37: ='PAINEL DE CONTROLE'!$G$8 -> 29012 | H37: 25198 | I37: =SUM(H37+F37) -> #REF! | J37: =SUM(I37-G37) -> #REF!
B38: =VLOOKUP(C38,[1]Saldo!A37:B31310,2,0) -> #ERROR! | C38: 315220-0204 | D38: ='[1]PARAMETROS PREVENTIVA'!$C703 -> #REF! | E38: ='[1]PARAMETROS PREVENTIVA'!$D703 -> #REF! | F38: ='[1]PARAMETROS PREVENTIVA'!$E703 -> #REF! | G38: ='PAINEL DE CONTROLE'!$G$8 -> 29012 | H38: 25198 | I38: =SUM(H38+F38) -> #REF! | J38: =SUM(I38-G38) -> #REF!
B39: =VLOOKUP(C39,[1]Saldo!A38:B31311,2,0) -> #ERROR! | C39: 315750-0129 | D39: ='[1]PARAMETROS PREVENTIVA'!$C704 -> #REF! | E39: ='[1]PARAMETROS PREVENTIVA'!$D704 -> #REF! | F39: ='[1]PARAMETROS PREVENTIVA'!$E704 -> #REF! | G39: ='PAINEL DE CONTROLE'!$G$8 -> 29012 | H39: 25198 | I39: =SUM(H39+F39) -> #REF! | J39: =SUM(I39-G39) -> #REF!
B40: =VLOOKUP(C40,[1]Saldo!A39:B31312,2,0) -> #ERROR! | C40: 344224-0209 | D40: ='[1]PARAMETROS PREVENTIVA'!$C705 -> #REF! | E40: ='[1]PARAMETROS PREVENTIVA'!$D705 -> #REF! | F40: ='[1]PARAMETROS PREVENTIVA'!$E705 -> #REF! | G40: ='PAINEL DE CONTROLE'!$G$8 -> 29012 | H40: 25198 | I40: =SUM(H40+F40) -> #REF! | J40: =SUM(I40-G40) -> #REF!
...

Sheet A3FLEX 02
A1: TPA3/FLEX 02
A2: SISTEMA | B2: PROG | C2: COD PROTHEUS | D2: COD TETRA | E2: DESCRIÇÃO | F2: QT | G2: FRENQ. TROCA | H2: HOR. ATUAL | I2: ULT. TROCA | J2: PREVISÃO | K2: HORAS P/ MANT. | L2: DATA DE MANUTENÇÃO | M2: OBSERVAÇÃO | N2: MANUTENTOR | O2: DATA DE MANUTENÇÃO | P2: OBSERVAÇÃO | Q2: MANUTENTOR | R2: DATA DE MANUTENÇÃO | S2: OBSERVAÇÃO | T2: MANUTENTOR | U2: DATA DE MANUTENÇÃO | V2: OBSERVAÇÃO | W2: MANUTENTOR | X2: DATA DE MANUTENÇÃO | Y2: OBSERVAÇÃO | Z2: MANUTENTOR | AA2: DATA DE MANUTENÇÃO | AB2: OBSERVAÇÃO | AC2: MANUTENTOR | AD2: DATA DE MANUTENÇÃO | AE2: OBSERVAÇÃO | AF2: MANUTENTOR | AG2: DATA DE MANUTENÇÃO | AH2: OBSERVAÇÃO | AI2: MANUTENTOR | AJ2: DATA DE MANUTENÇÃO | AK2: OBSERVAÇÃO | AL2: MANUTENTOR | AM2: DATA DE MANUTENÇÃO | AN2: OBSERVAÇÃO | AO2: MANUTENTOR | AP2: DATA DE MANUTENÇÃO | AQ2: OBSERVAÇÃO | AR2: MANUTENTOR | AS2: DATA DE MANUTENÇÃO | AT2: OBSERVAÇÃO | AU2: MANUTENTOR
A3: BOMBA DE PEROXIDO | C3: =VLOOKUP(D3,[1]Saldo!A2:B31275,2,0) -> #ERROR! | D3: 1255557-0000 | E3: JUNTA DE VEDACAO | F3: ='[1]PARAMETROS PREVENTIVA'!$D168 -> #REF! | G3: ='[1]PARAMETROS PREVENTIVA'!$E168 -> #REF! | H3: ='PAINEL DE CONTROLE'!$J$5 -> 6544 | I3: 0 | J3: =I3+G3 -> #REF! | K3: =SUM(J3-H3) -> #REF!
C4: =VLOOKUP(D4,[1]Saldo!A3:B31276,2,0) -> #ERROR! | D4: 927422-0005 | E4: O-RING 36.2X3 SILICON | F4: ='[1]PARAMETROS PREVENTIVA'!$D169 -> #REF! | G4: ='[1]PARAMETROS PREVENTIVA'!$E169 -> #REF! | H4: ='PAINEL DE CONTROLE'!$J$5 -> 6544 | I4: 0 | J4: =I4+G4 -> #REF! | K4: =SUM(J4-H4) -> #REF!
C5: =VLOOKUP(D5,[1]Saldo!A4:B31277,2,0) -> #ERROR! | D5: 927422-0006 | E5: O-RING 42.2X3 SILICON | F5: ='[1]PARAMETROS PREVENTIVA'!$D170 -> #REF! | G5: ='[1]PARAMETROS PREVENTIVA'!$E170 -> #REF! | H5: ='PAINEL DE CONTROLE'!$J$5 -> 6544 | I5: 0 | J5: =I5+G5 -> #REF! | K5: =SUM(J5-H5) -> #REF!
C6: =VLOOKUP(D6,[1]Saldo!A5:B31278,2,0) -> #ERROR! | D6: 315229-0103 | E6: Square Ring, 23,1x30,1x3,7 | F6: ='[1]PARAMETROS PREVENTIVA'!$D171 -> #REF! | G6: ='[1]PARAMETROS PREVENTIVA'!$E171 -> #REF! | H6: ='PAINEL DE CONTROLE'!$J$5 -> 6544 | I6: 0 | J6: =I6+G6 -> #REF! | K6: =SUM(J6-H6) -> #REF!
C7: =VLOOKUP(D7,[1]Saldo!A6:B31279,2,0) -> #ERROR! | D7: 315229-0104 | E7: Square Ring, 35,8x42,8x3,7 mm 1"1/2 FDA | F7: ='[1]PARAMETROS PREVENTIVA'!$D172 -> #REF! | G7: ='[1]PARAMETROS PREVENTIVA'!$E172 -> #REF! | H7: ='PAINEL DE CONTROLE'!$J$5 -> 6544 | I7: 0 | J7: =I7+G7 -> #REF! | K7: =SUM(J7-H7) -> #REF!
C8: =VLOOKUP(D8,[1]Saldo!A7:B31280,2,0) -> #ERROR! | D8: 315229-0105 | E8: Square Ring, 48,5x55,5x3,7 mm 2" FDA | F8: ='[1]PARAMETROS PREVENTIVA'!$D173 -> #REF! | G8: ='[1]PARAMETROS PREVENTIVA'!$E173 -> #REF! | H8: ='PAINEL DE CONTROLE'!$J$5 -> 6544 | I8: 0 | J8: =I8+G8 -> #REF! | K8: =SUM(J8-H8) -> #REF!
C9: =VLOOKUP(D9,[1]Saldo!A8:B31281,2,0) -> #ERROR! | D9: 315229-0107 | E9: Gaxeta 73,9x80,9x3,7 mm 2"1/2 FDA | F9: ='[1]PARAMETROS PREVENTIVA'!$D174 -> #REF! | G9: ='[1]PARAMETROS PREVENTIVA'!$E174 -> #REF! | H9: ='PAINEL DE CONTROLE'!$J$5 -> 6544 | I9: 0 | J9: =I9+G9 -> #REF! | K9: =SUM(J9-H9) -> #REF!
C10: =VLOOKUP(D10,[1]Saldo!A9:B31282,2,0) -> #ERROR! | D10: 2734102-0000 | E10: Casquilho | F10: ='[1]PARAMETROS PREVENTIVA'!$D175 -> #REF! | G10: ='[1]PARAMETROS PREVENTIVA'!$E175 -> #REF! | H10: ='PAINEL DE CONTROLE'!$J$5 -> 6544 | I10: 0 | J10: =I10+G10 -> #REF! | K10: =SUM(J10-H10) -> #REF!
C11: =VLOOKUP(D11,[1]Saldo!A10:B31283,2,0) -> #ERROR! | D11: 90458-0274 | E11: Disco para acoplamento | F11: ='[1]PARAMETROS PREVENTIVA'!$D176 -> #REF! | G11: ='[1]PARAMETROS PREVENTIVA'!$E176 -> #REF! | H11: ='PAINEL DE CONTROLE'!$J$5 -> 6544 | I11: 0 | J11: =I11+G11 -> #REF! | K11: =SUM(J11-H11) -> #REF!
C12: =VLOOKUP(D12,[1]Saldo!A11:B31284,2,0) -> #ERROR! | D12: 90607-0389 | E12: Rolamento W 6203-2RS2/VT127 | F12: ='[1]PARAMETROS PREVENTIVA'!$D177 -> #REF! | G12: ='[1]PARAMETROS PREVENTIVA'!$E177 -> #REF! | H12: ='PAINEL DE CONTROLE'!$J$5 -> 6544 | I12: 0 | J12: =I12+G12 -> #REF! | K12: =SUM(J12-H12) -> #REF!
C13: =VLOOKUP(D13,[1]Saldo!A12:B31285,2,0) -> #ERROR! | D13: 90091-0412 | E13: Seal Ring | F13: ='[1]PARAMETROS PREVENTIVA'!$D178 -> #REF! | G13: ='[1]PARAMETROS PREVENTIVA'!$E178 -> #REF! | H13: ='PAINEL DE CONTROLE'!$J$5 -> 6544 | I13: 0 | J13: =I13+G13 -> #REF! | K13: =SUM(J13-H13) -> #REF!
A14: ROLAMENTOS DE ROLOS | C14: =VLOOKUP(D14,[1]Saldo!A13:B31286,2,0) -> #ERROR! | D14: 90458-1704 | E14: ROLAMENTO DE ESFERAS | F14: 7 | G14: 2000 | H14: ='PAINEL DE CONTROLE'!$J$5 -> 6544 | I14: 0 | J14: =I14+G14 -> 2000 | K14: =SUM(J14-H14) -> -4544
C15: =VLOOKUP(D15,[1]Saldo!A14:B31287,2,0) -> #ERROR! | D15: 90214-0303 | E15: ANEL | F15: 7 | G15: 2000 | H15: ='PAINEL DE CONTROLE'!$J$5 -> 6544 | I15: 0 | J15: =I15+G15 -> 2000 | K15: =SUM(J15-H15) -> -4544
C16: =VLOOKUP(D16,[1]Saldo!A15:B31288,2,0) -> #ERROR! | D16: 315753-0130 | E16: Anel de retenção DIN 472 47 SS | F16: 1 | G16: 3000 | H16: ='PAINEL DE CONTROLE'!$J$5 -> 6544 | I16: 0 | J16: =I16+G16 -> 3000 | K16: =SUM(J16-H16) -> -3544
C17: =VLOOKUP(D17,[1]Saldo!A16:B31289,2,0) -> #ERROR! | D17: 315753-0119 | E17: ANEL DE FR DIN 471 25 A2 | F17: 1 | G17: 3000 | H17: ='PAINEL DE CONTROLE'!$J$5 -> 6544 | I17: 0 | J17: =I17+G17 -> 3000 | K17: =SUM(J17-H17) -> -3544
C18: =VLOOKUP(D18,[1]Saldo!A17:B31290,2,0) -> #ERROR! | D18: 90608-5674 | E18: ROLAMENTO DE ESFERAS | F18: 1 | G18: 3000 | H18: ='PAINEL DE CONTROLE'!$J$5 -> 6544 | I18: 0 | J18: =I18+G18 -> 3000 | K18: =SUM(J18-H18) -> -3544
C19: =VLOOKUP(D19,[1]Saldo!A18:B31291,2,0) -> #ERROR! | D19: 90459-1650 | E19: ANEL VEDANTE | F19: 1 | G19: 3000 | H19: ='PAINEL DE CONTROLE'!$J$5 -> 6544 | I19: 0 | J19: =I19+G19 -> 3000 | K19: =SUM(J19-H19) -> -3544
C20: =VLOOKUP(D20,[1]Saldo!A19:B31292,2,0) -> #ERROR! | D20: 90600-6017 | E20: VEDANTE | F20: 2 | G20: 3000 | H20: ='PAINEL DE CONTROLE'!$J$5 -> 6544 | I20: 0 | J20: =I20+G20 -> 3000 | K20: =SUM(J20-H20) -> -3544
C21: =VLOOKUP(D21,[1]Saldo!A20:B31293,2,0) -> #ERROR! | D21: 90601-2426 | E21: Casquilho | F21: 2 | G21: 3000 | H21: ='PAINEL DE CONTROLE'!$J$5 -> 6544 | I21: 0 | J21: =I21+G21 -> 3000 | K21: =SUM(J21-H21) -> -3544
C22: =VLOOKUP(D22,[1]Saldo!A21:B31294,2,0) -> #ERROR! | D22: 90602-0271 | E22: VEDANTE | F22: 8 | G22: 3000 | H22: ='PAINEL DE CONTROLE'!$J$5 -> 6544 | I22: 0 | J22: =I22+G22 -> 3000 | K22: =SUM(J22-H22) -> -3544
C23: =VLOOKUP(D23,[1]Saldo!A22:B31295,2,0) -> #ERROR! | D23: 90606-6965 | E23: Rolamento | F23: 4 | G23: 3000 | H23: ='PAINEL DE CONTROLE'!$J$5 -> 6544 | I23: 0 | J23: =I23+G23 -> 3000 | K23: =SUM(J23-H23) -> -3544
C24: =VLOOKUP(D24,[1]Saldo!A23:B31296,2,0) -> #ERROR! | D24: 315205-0509 | E24: O-ring 10,78x2,62 mm | F24: 4 | G24: 3000 | H24: ='PAINEL DE CONTROLE'!$J$5 -> 6544 | I24: 0 | J24: =I24+G24 -> 3000 | K24: =SUM(J24-H24) -> -3544
C25: =VLOOKUP(D25,[1]Saldo!A24:B31297,2,0) -> #ERROR! | D25: 315205-0734 | E25: O-ring 47,29x2,62 mm | F25: 4 | G25: 3000 | H25: ='PAINEL DE CONTROLE'!$J$5 -> 6544 | I25: 0 | J25: =I25+G25 -> 3000 | K25: =SUM(J25-H25) -> -3544
